Workbook

Sheet Budget
A1: Budget-Plan Schweiz
A2: Gelbe Felder ausfüllen, alles andere rechnet sich selbst. Takt = wie oft der Betrag anfällt.
A4: Einnahmen
A5: Bezeichnung | B5: Betrag | C5: Takt | F5: pro Monat
A6: Nettolohn | B6: 5800 | C6: monatlich | F6: =IF(B6="",0,B6*IFERROR(VLOOKUP(C6,Listen!$A$1:$B$4,2,FALSE),12)/12)
A7: 13. Monatslohn | B7: 5800 | C7: jährlich | F7: =IF(B7="",0,B7*IFERROR(VLOOKUP(C7,Listen!$A$1:$B$4,2,FALSE),12)/12)
C8: monatlich | F8: =IF(B8="",0,B8*IFERROR(VLOOKUP(C8,Listen!$A$1:$B$4,2,FALSE),12)/12)
C9: monatlich | F9: =IF(B9="",0,B9*IFERROR(VLOOKUP(C9,Listen!$A$1:$B$4,2,FALSE),12)/12)
A11: Ausgaben
A12: Bezeichnung | B12: Betrag | C12: Takt | D12: Art | E12: Wohnen | F12: pro Monat | G12: davon zurücklegen
A13: Miete inkl. Nebenkosten | B13: 1850 | C13: monatlich | D13: Muss | E13: ja | F13: =IF(B13="",0,B13*IFERROR(VLOOKUP(C13,Listen!$A$1:$B$4,2,FALSE),12)/12) | G13: =IF(C13="monatlich",0,F13)
A14: Krankenkasse Prämien | B14: 420 | C14: monatlich | D14: Muss | F14: =IF(B14="",0,B14*IFERROR(VLOOKUP(C14,Listen!$A$1:$B$4,2,FALSE),12)/12) | G14: =IF(C14="monatlich",0,F14)
A15: Franchise und Selbstbehalt | B15: 1000 | C15: jährlich | D15: Muss | F15: =IF(B15="",0,B15*IFERROR(VLOOKUP(C15,Listen!$A$1:$B$4,2,FALSE),12)/12) | G15: =IF(C15="monatlich",0,F15)
A16: Steuern (letzte Rechnung) | B16: 8400 | C16: jährlich | D16: Muss | F16: =IF(B16="",0,B16*IFERROR(VLOOKUP(C16,Listen!$A$1:$B$4,2,FALSE),12)/12) | G16: =IF(C16="monatlich",0,F16)
A17: Hausrat und Haftpflicht | B17: 380 | C17: jährlich | D17: Muss | F17: =IF(B17="",0,B17*IFERROR(VLOOKUP(C17,Listen!$A$1:$B$4,2,FALSE),12)/12) | G17: =IF(C17="monatlich",0,F17)
A18: Radio- und TV-Gebühr | B18: 335 | C18: jährlich | D18: Muss | F18: =IF(B18="",0,B18*IFERROR(VLOOKUP(C18,Listen!$A$1:$B$4,2,FALSE),12)/12) | G18: =IF(C18="monatlich",0,F18)
A19: Handy und Internet | B19: 90 | C19: monatlich | D19: Muss | F19: =IF(B19="",0,B19*IFERROR(VLOOKUP(C19,Listen!$A$1:$B$4,2,FALSE),12)/12) | G19: =IF(C19="monatlich",0,F19)
A20: ÖV und Mobilität | B20: 150 | C20: monatlich | D20: Muss | F20: =IF(B20="",0,B20*IFERROR(VLOOKUP(C20,Listen!$A$1:$B$4,2,FALSE),12)/12) | G20: =IF(C20="monatlich",0,F20)
A21: Lebensmittel und Haushalt | B21: 700 | C21: monatlich | D21: Muss | F21: =IF(B21="",0,B21*IFERROR(VLOOKUP(C21,Listen!$A$1:$B$4,2,FALSE),12)/12) | G21: =IF(C21="monatlich",0,F21)
A22: Kleider | B22: 1200 | C22: jährlich | D22: Kann | F22: =IF(B22="",0,B22*IFERROR(VLOOKUP(C22,Listen!$A$1:$B$4,2,FALSE),12)/12) | G22: =IF(C22="monatlich",0,F22)
A23: Freizeit und Ausgang | B23: 300 | C23: monatlich | D23: Kann | F23: =IF(B23="",0,B23*IFERROR(VLOOKUP(C23,Listen!$A$1:$B$4,2,FALSE),12)/12) | G23: =IF(C23="monatlich",0,F23)
A24: Ferien | B24: 3000 | C24: jährlich | D24: Kann | F24: =IF(B24="",0,B24*IFERROR(VLOOKUP(C24,Listen!$A$1:$B$4,2,FALSE),12)/12) | G24: =IF(C24="monatlich",0,F24)
A25: Geschenke | B25: 600 | C25: jährlich | D25: Kann | F25: =IF(B25="",0,B25*IFERROR(VLOOKUP(C25,Listen!$A$1:$B$4,2,FALSE),12)/12) | G25: =IF(C25="monatlich",0,F25)
A26: Säule 3a | B26: 300 | C26: monatlich | D26: Sparen | F26: =IF(B26="",0,B26*IFERROR(VLOOKUP(C26,Listen!$A$1:$B$4,2,FALSE),12)/12) | G26: =IF(C26="monatlich",0,F26)
C27: monatlich | D27: Muss | F27: =IF(B27="",0,B27*IFERROR(VLOOKUP(C27,Listen!$A$1:$B$4,2,FALSE),12)/12) | G27: =IF(C27="monatlich",0,F27)
C28: monatlich | D28: Muss | F28: =IF(B28="",0,B28*IFERROR(VLOOKUP(C28,Listen!$A$1:$B$4,2,FALSE),12)/12) | G28: =IF(C28="monatlich",0,F28)
C29: monatlich | D29: Muss | F29: =IF(B29="",0,B29*IFERROR(VLOOKUP(C29,Listen!$A$1:$B$4,2,FALSE),12)/12) | G29: =IF(C29="monatlich",0,F29)
C30: monatlich | D30: Muss | F30: =IF(B30="",0,B30*IFERROR(VLOOKUP(C30,Listen!$A$1:$B$4,2,FALSE),12)/12) | G30: =IF(C30="monatlich",0,F30)
C31: monatlich | D31: Muss | F31: =IF(B31="",0,B31*IFERROR(VLOOKUP(C31,Listen!$A$1:$B$4,2,FALSE),12)/12) | G31: =IF(C31="monatlich",0,F31)
C32: monatlich | D32: Muss | F32: =IF(B32="",0,B32*IFERROR(VLOOKUP(C32,Listen!$A$1:$B$4,2,FALSE),12)/12) | G32: =IF(C32="monatlich",0,F32)
C33: monatlich | D33: Muss | F33: =IF(B33="",0,B33*IFERROR(VLOOKUP(C33,Listen!$A$1:$B$4,2,FALSE),12)/12) | G33: =IF(C33="monatlich",0,F33)
C34: monatlich | D34: Muss | F34: =IF(B34="",0,B34*IFERROR(VLOOKUP(C34,Listen!$A$1:$B$4,2,FALSE),12)/12) | G34: =IF(C34="monatlich",0,F34)
C35: monatlich | D35: Muss | F35: =IF(B35="",0,B35*IFERROR(VLOOKUP(C35,Listen!$A$1:$B$4,2,FALSE),12)/12) | G35: =IF(C35="monatlich",0,F35)
C36: monatlich | D36: Muss | F36: =IF(B36="",0,B36*IFERROR(VLOOKUP(C36,Listen!$A$1:$B$4,2,FALSE),12)/12) | G36: =IF(C36="monatlich",0,F36)
C37: monatlich | D37: Muss | F37: =IF(B37="",0,B37*IFERROR(VLOOKUP(C37,Listen!$A$1:$B$4,2,FALSE),12)/12) | G37: =IF(C37="monatlich",0,F37)
C38: monatlich | D38: Muss | F38: =IF(B38="",0,B38*IFERROR(VLOOKUP(C38,Listen!$A$1:$B$4,2,FALSE),12)/12) | G38: =IF(C38="monatlich",0,F38)
... C42: monatlich | D42: Muss | F42: =IF(B42="",0,B42*IFERROR(VLOOKUP(C42,Listen!$A$1:$B$4,2,FALSE),12)/12) | G42: =IF(C42="monatlich",0,F42)
A44: Auswertung pro Monat
A45: Einnahmen | B45: =SUM(F6:F9)
A46: Ausgaben (inkl. Sparen) | B46: =SUM(F13:F42)
...

Sheet Jahres-Tracker
A1: Jahres-Tracker: was wirklich rausging
A2: Trag am Monatsende die tatsächlichen Beträge ein. Rot = mehr als geplant.
A4: Posten | B4: Plan / Monat | C4: Jan | D4: Feb | E4: Mär | F4: Apr | G4: Mai | H4: Jun | I4: Jul | J4: Aug | K4: Sep | L4: Okt | M4: Nov | N4: Dez | O4: Ø Ist
A5: =IF(Budget!A13="","",Budget!A13) | B5: =IF(Budget!A13="","",Budget!F13) | O5: =IF(COUNT(C5:N5)=0,"",AVERAGE(C5:N5))
A6: =IF(Budget!A14="","",Budget!A14) | B6: =IF(Budget!A14="","",Budget!F14) | O6: =IF(COUNT(C6:N6)=0,"",AVERAGE(C6:N6))
A7: =IF(Budget!A15="","",Budget!A15) | B7: =IF(Budget!A15="","",Budget!F15) | O7: =IF(COUNT(C7:N7)=0,"",AVERAGE(C7:N7))
A8: =IF(Budget!A16="","",Budget!A16) | B8: =IF(Budget!A16="","",Budget!F16) | O8: =IF(COUNT(C8:N8)=0,"",AVERAGE(C8:N8))
A9: =IF(Budget!A17="","",Budget!A17) | B9: =IF(Budget!A17="","",Budget!F17) | O9: =IF(COUNT(C9:N9)=0,"",AVERAGE(C9:N9))
A10: =IF(Budget!A18="","",Budget!A18) | B10: =IF(Budget!A18="","",Budget!F18) | O10: =IF(COUNT(C10:N10)=0,"",AVERAGE(C10:N10))
A11: =IF(Budget!A19="","",Budget!A19) | B11: =IF(Budget!A19="","",Budget!F19) | O11: =IF(COUNT(C11:N11)=0,"",AVERAGE(C11:N11))
A12: =IF(Budget!A20="","",Budget!A20) | B12: =IF(Budget!A20="","",Budget!F20) | O12: =IF(COUNT(C12:N12)=0,"",AVERAGE(C12:N12))
A13: =IF(Budget!A21="","",Budget!A21) | B13: =IF(Budget!A21="","",Budget!F21) | O13: =IF(COUNT(C13:N13)=0,"",AVERAGE(C13:N13))
A14: =IF(Budget!A22="","",Budget!A22) | B14: =IF(Budget!A22="","",Budget!F22) | O14: =IF(COUNT(C14:N14)=0,"",AVERAGE(C14:N14))
A15: =IF(Budget!A23="","",Budget!A23) | B15: =IF(Budget!A23="","",Budget!F23) | O15: =IF(COUNT(C15:N15)=0,"",AVERAGE(C15:N15))
A16: =IF(Budget!A24="","",Budget!A24) | B16: =IF(Budget!A24="","",Budget!F24) | O16: =IF(COUNT(C16:N16)=0,"",AVERAGE(C16:N16))
... A34: =IF(Budget!A42="","",Budget!A42) | B34: =IF(Budget!A42="","",Budget!F42) | O34: =IF(COUNT(C34:N34)=0,"",AVERAGE(C34:N34))
A35: Summe | B35: =SUM(B5:B34) | C35: =IF(COUNT(C5:C34)=0,"",SUM(C5:C34)) | D35: =IF(COUNT(D5:D34)=0,"",SUM(D5:D34)) | E35: =IF(COUNT(E5:E34)=0,"",SUM(E5:E34)) | F35: =IF(COUNT(F5:F34)=0,"",SUM(F5:F34)) | G35: =IF(COUNT(G5:G34)=0,"",SUM(G5:G34)) | H35: =IF(COUNT(H5:H34)=0,"",SUM(H5:H34)) | I35: =IF(COUNT(I5:I34)=0,"",SUM(I5:I34)) | J35: =IF(COUNT(J5:J34)=0,"",SUM(J5:J34)) | ... N35: =IF(COUNT(N5:N34)=0,"",SUM(N5:N34))

Sheet Anleitung
A1: Budget-Plan Schweiz — so geht's
A3: 1. Blatt „Budget“: Einnahmen eintragen. Den 13. Monatslohn als eigene Zeile mit Takt „jährlich“.
A4: 2. Alle Ausgaben eintragen, so wie sie kommen: Miete monatlich, Steuern jährlich (letzte Steuerrechnung),
A5: Hausrat jährlich. Die Spalte „pro Monat“ rechnet alles auf den Monat um.
A6: 3. Art wählen: Muss (kurzfristig nicht änderbar), Kann (änderbar), Sparen (Säule 3a, Sparkonto, Tilgung).
A7: 4. Auswertung lesen: Übrig/fehlt, Dauerauftrag fürs Rückstellungskonto, Muss/Kann/Sparen, Notreserve.
A8: 5. Blatt „Jahres-Tracker“: am Monatsende die tatsächlichen Beträge eintragen. Rot = mehr als 10 % über Plan.
A10: Das Rückstellungskonto: In der Schweiz kommen die Steuern bei den meisten als Rechnung, nicht als Lohnabzug.
A11: Den Betrag aus der Auswertung per Dauerauftrag auf ein zweites Konto überweisen und alle Jahresrechnungen
A12: von dort bezahlen. So bringt keine Rechnung das Budget aus dem Gleichgewicht.
A14: Warnzeichen: Übrig negativ (rot) oder Wohnkosten über einem Drittel des Einkommens (rot).
A15: Hilfe, wenn es nicht aufgeht: kantonale Budget- und Schuldenberatungen, kostenlos (Übersicht: schulden.ch).
... A18: © aban news · abannews.com

Sheet Listen
A1: monatlich | B1: 12 | D1: Muss
A2: pro Quartal | B2: 4 | D2: Kann
A3: halbjährlich | B3: 2 | D3: Sparen
A4: jährlich | B4: 1
