Workbook

Sheet Plan
B1: Debt Payoff Planner
B2: Fill in the yellow cells. The plan works out, month by month, when you will be debt free.
B5: Debt | C5: Balance | D5: Interest % / yr | E5: Minimum payment | F5: Paid off (month) | G5: Warning
B6: Credit card | C6: 3200 | D6: 12 | E6: 120 | F6: ='Monthly Plan'!D3 | G6: =IF(AND(C6>0,E6<=C6*D6/100/12),"Payment below interest!","")
B7: Personal loan | C7: 15000 | D7: 7.9 | E7: 350 | F7: ='Monthly Plan'!J3 | G7: =IF(AND(C7>0,E7<=C7*D7/100/12),"Payment below interest!","")
B8: Car loan | C8: 9000 | D8: 4.9 | E8: 280 | F8: ='Monthly Plan'!P3 | G8: =IF(AND(C8>0,E8<=C8*D8/100/12),"Payment below interest!","")
B9: Family loan | C9: 2000 | D9: 0 | E9: 50 | F9: ='Monthly Plan'!V3 | G9: =IF(AND(C9>0,E9<=C9*D9/100/12),"Payment below interest!","")
C10: 0 | D10: 0 | E10: 0 | F10: ='Monthly Plan'!AB3 | G10: =IF(AND(C10>0,E10<=C10*D10/100/12),"Payment below interest!","")
C11: 0 | D11: 0 | E11: 0 | F11: ='Monthly Plan'!AH3 | G11: =IF(AND(C11>0,E11<=C11*D11/100/12),"Payment below interest!","")
C12: 0 | D12: 0 | E12: 0 | F12: ='Monthly Plan'!AN3 | G12: =IF(AND(C12>0,E12<=C12*D12/100/12),"Payment below interest!","")
C13: 0 | D13: 0 | E13: 0 | F13: ='Monthly Plan'!AT3 | G13: =IF(AND(C13>0,E13<=C13*D13/100/12),"Payment below interest!","")
B16: Extra per month | C16: 300
B17: Method | C17: Avalanche | D17: Avalanche = highest interest first (cheapest) · Snowball = smallest balance first
B18: Start month | C18: =DATE(YEAR(TODAY()),MONTH(TODAY())+1,1)
B20: Result
B21: Debt free after (months) | C21: ='Monthly Plan'!BA2
B22: Debt free in | C22: =IF(ISNUMBER(C21),EDATE(C18,C21-1),"—")
B23: Total interest (chosen method) | C23: ='Monthly Plan'!BA1
B24: Interest with the other method | C24: ='Calc other method'!BA1
B25: Interest with minimum payments only | C25: ='Calc no extra'!BA1
B26: Saved by the extra payment | C26: =C25-C23
B27: Debt free with minimums only (months) | C27: ='Calc no extra'!BA2
B29: Tip: the avalanche costs the least interest. The snowball gives you a quick first win. Pick the method you will stick with.

Sheet How to use
A1: Debt Payoff Planner — how to use it
A3: 1. Sheet „Plan“: enter up to 8 debts: balance, yearly interest rate from your contract, current minimum payment.
A4: 2. Enter the extra amount you can pay each month. Even 50 a month shortens the payoff noticeably.
A5: 3. Pick a method: Avalanche (highest interest first, cheapest) or Snowball (smallest balance first).
A6: 4. Read the result: debt-free date, total interest, comparison with the other method and with minimums only.
A7: 5. Sheet „Monthly Plan“: month by month, what happens to each debt. Freed-up payments roll to the next debt.
A9: Red in the „Warning“ column: the payment does not even cover the interest, so the debt grows. Fix that first.
A10: Build an emergency fund of about three months of expenses first, then pay down debt.
A11: Works with any currency. Google Sheets: upload to Google Drive → Open with → Google Sheets.
A13: Model calculation without fees or penalty interest, not financial advice. Personal use only.
A14: © aban news · abannews.com

Sheet Monthly Plan
A1: Method | B1: =Plan!$C$17 | AZ1: Total interest | BA1: =SUM(D7:D366)+SUM(J7:J366)+SUM(P7:P366)+SUM(V7:V366)+SUM(AB7:AB366)+SUM(AH7:AH366)+SUM(AN7:AN366)+SUM(AT7:AT366)
A2: Extra per month | B2: =Plan!$C$16 | AZ2: Debt free after months | BA2: =IFERROR(MATCH(0,BC7:BC366,0),"30+ years")
A3: Budget per month | B3: =SUMPRODUCT((Plan!$C$6:$C$13>0)*Plan!$E$6:$E$13)+B2 | C3: paid off in month | D3: =IF(Plan!C6<=0,"",IFERROR(MATCH(0,H7:H366,0),"30+ yrs")) | I3: paid off in month | J3: =IF(Plan!C7<=0,"",IFERROR(MATCH(0,N7:N366,0),"30+ yrs")) | O3: paid off in month | P3: =IF(Plan!C8<=0,"",IFERROR(MATCH(0,T7:T366,0),"30+ yrs")) | U3: paid off in month | V3: =IF(Plan!C9<=0,"",IFERROR(MATCH(0,Z7:Z366,0),"30+ yrs")) | AA3: paid off in month | AB3: =IF(Plan!C10<=0,"",IFERROR(MATCH(0,AF7:AF366,0),"30+ yrs")) | AG3: paid off in month | AH3: =IF(Plan!C11<=0,"",IFERROR(MATCH(0,AL7:AL366,0),"30+ yrs")) | AM3: paid off in month | AN3: =IF(Plan!C12<=0,"",IFERROR(MATCH(0,AR7:AR366,0),"30+ yrs")) | AS3: paid off in month | AT3: =IF(Plan!C13<=0,"",IFERROR(MATCH(0,AX7:AX366,0),"30+ yrs"))
C4: =Plan!B6 | I4: =Plan!B7 | O4: =Plan!B8 | U4: =Plan!B9 | AA4: =Plan!B10 | AG4: =Plan!B11 | AM4: =Plan!B12 | AS4: =Plan!B13
C5: =IF(Plan!C6<=0,-1E+15,IF($B$1="Avalanche",Plan!D6*1E+9-Plan!C6,-Plan!C6*1000+Plan!D6)) | D5: Rank | E5: =1+(C$5>C$5)+(I$5>C$5)+(O$5>C$5)+(U$5>C$5)+(AA$5>C$5)+(AG$5>C$5)+(AM$5>C$5)+(AS$5>C$5)+0 | I5: =IF(Plan!C7<=0,-1E+15,IF($B$1="Avalanche",Plan!D7*1E+9-Plan!C7,-Plan!C7*1000+Plan!D7)) | J5: Rank | K5: =1+(C$5>I$5)+(I$5>I$5)+(O$5>I$5)+(U$5>I$5)+(AA$5>I$5)+(AG$5>I$5)+(AM$5>I$5)+(AS$5>I$5)+(C$5=I$5) | O5: =IF(Plan!C8<=0,-1E+15,IF($B$1="Avalanche",Plan!D8*1E+9-Plan!C8,-Plan!C8*1000+Plan!D8)) | P5: Rank | Q5: =1+(C$5>O$5)+(I$5>O$5)+(O$5>O$5)+(U$5>O$5)+(AA$5>O$5)+(AG$5>O$5)+(AM$5>O$5)+(AS$5>O$5)+(C$5=O$5)+(I$5=O$5) | U5: =IF(Plan!C9<=0,-1E+15,IF($B$1="Avalanche",Plan!D9*1E+9-Plan!C9,-Plan!C9*1000+Plan!D9)) | V5: Rank | W5: =1+(C$5>U$5)+(I$5>U$5)+(O$5>U$5)+(U$5>U$5)+(AA$5>U$5)+(AG$5>U$5)+(AM$5>U$5)+(AS$5>U$5)+(C$5=U$5)+(I$5=U$5)+(O$5=U$5) | AA5: =IF(Plan!C10<=0,-1E+15,IF($B$1="Avalanche",Plan!D10*1E+9-Plan!C10,-Plan!C10*1000+Plan!D10)) | AB5: Rank | AC5: =1+(C$5>AA$5)+(I$5>AA$5)+(O$5>AA$5)+(U$5>AA$5)+(AA$5>AA$5)+(AG$5>AA$5)+(AM$5>AA$5)+(AS$5>AA$5)+(C$5=AA$5)+(I$5=AA$5)+(O$5=AA$5)+(U$5=AA$5) | AG5: =IF(Plan!C11<=0,-1E+15,IF($B$1="Avalanche",Plan!D11*1E+9-Plan!C11,-Plan!C11*1000+Plan!D11)) | AH5: Rank | AI5: =1+(C$5>AG$5)+(I$5>AG$5)+(O$5>AG$5)+(U$5>AG$5)+(AA$5>AG$5)+(AG$5>AG$5)+(AM$5>AG$5)+(AS$5>AG$5)+(C$5=AG$5)+(I$5=AG$5)+(O$5=AG$5)+(U$5=AG$5)+(AA$5=AG$5) | AM5: =IF(Plan!C12<=0,-1E+15,IF($B$1="Avalanche",Plan!D12*1E+9-Plan!C12,-Plan!C12*1000+Plan!D12)) | AN5: Rank | AO5: =1+(C$5>AM$5)+(I$5>AM$5)+(O$5>AM$5)+(U$5>AM$5)+(AA$5>AM$5)+(AG$5>AM$5)+(AM$5>AM$5)+(AS$5>AM$5)+(C$5=AM$5)+(I$5=AM$5)+(O$5=AM$5)+(U$5=AM$5)+(AA$5=AM$5)+(AG$5=AM$5) | AS5: =IF(Plan!C13<=0,-1E+15,IF($B$1="Avalanche",Plan!D13*1E+9-Plan!C13,-Plan!C13*1000+Plan!D13)) | AT5: Rank | AU5: =1+(C$5>AS$5)+(I$5>AS$5)+(O$5>AS$5)+(U$5>AS$5)+(AA$5>AS$5)+(AG$5>AS$5)+(AM$5>AS$5)+(AS$5>AS$5)+(C$5=AS$5)+(I$5=AS$5)+(O$5=AS$5)+(U$5=AS$5)+(AA$5=AS$5)+(AG$5=AS$5)+(AM$5=AS$5)
A6: Month | B6: free for extra | C6: Start | D6: Interest | E6: Minimum | F6: Remaining | G6: Extra | H6: End | I6: Start | J6: Interest | K6: Minimum | L6: Remaining | M6: Extra | N6: End | O6: Start | P6: Interest | Q6: Minimum | R6: Remaining | S6: Extra | T6: End | U6: Start | V6: Interest | W6: Minimum | X6: Remaining | Y6: Extra | Z6: End | AA6: Start | AB6: Interest | AC6: Minimum | AD6: Remaining | AE6: Extra | AF6: End | AG6: Start | AH6: Interest | AI6: Minimum | AJ6: Remaining | AK6: Extra | AL6: End | AM6: Start | AN6: Interest | AO6: Minimum | AP6: Remaining | AQ6: Extra | AR6: End | AS6: Start | AT6: Interest | AU6: Minimum | AV6: Remaining | AW6: Extra | AX6: End | BC6: total owed
A7: 1 | B7: =MAX(0,$B$3-(E7+K7+Q7+W7+AC7+AI7+AO7+AU7)) | C7: =MAX(0,Plan!C6) | D7: =C7*Plan!D6/100/12 | E7: =MIN(Plan!E6,C7+D7) | F7: =C7+D7-E7 | G7: =MIN(F7,MAX(0,$B7-((K$5<E$5)*L7+(Q$5<E$5)*R7+(W$5<E$5)*X7+(AC$5<E$5)*AD7+(AI$5<E$5)*AJ7+(AO$5<E$5)*AP7+(AU$5<E$5)*AV7))) | H7: =IF(F7-G7<0.005,0,F7-G7) | I7: =MAX(0,Plan!C7) | J7: =I7*Plan!D7/100/12 | K7: =MIN(Plan!E7,I7+J7) | L7: =I7+J7-K7 | M7: =MIN(L7,MAX(0,$B7-((E$5<K$5)*F7+(Q$5<K$5)*R7+(W$5<K$5)*X7+(AC$5<K$5)*AD7+(AI$5<K$5)*AJ7+(AO$5<K$5)*AP7+(AU$5<K$5)*AV7))) | N7: =IF(L7-M7<0.005,0,L7-M7) | O7: =MAX(0,Plan!C8) | P7: =O7*Plan!D8/100/12 | Q7: =MIN(Plan!E8,O7+P7) | R7: =O7+P7-Q7 | S7: =MIN(R7,MAX(0,$B7-((E$5<Q$5)*F7+(K$5<Q$5)*L7+(W$5<Q$5)*X7+(AC$5<Q$5)*AD7+(AI$5<Q$5)*AJ7+(AO$5<Q$5)*AP7+(AU$5<Q$5)*AV7))) | T7: =IF(R7-S7<0.005,0,R7-S7) | U7: =MAX(0,Plan!C9) | V7: =U7*Plan!D9/100/12 | W7: =MIN(Plan!E9,U7+V7) | X7: =U7+V7-W7 | Y7: =MIN(X7,MAX(0,$B7-((E$5<W$5)*F7+(K$5<W$5)*L7+(Q$5<W$5)*R7+(AC$5<W$5)*AD7+(AI$5<W$5)*AJ7+(AO$5<W$5)*AP7+(AU$5<W$5)*AV7))) | Z7: =IF(X7-Y7<0.005,0,X7-Y7) | AA7: =MAX(0,Plan!C10) | AB7: =AA7*Plan!D10/100/12 | AC7: =MIN(Plan!E10,AA7+AB7) | AD7: =AA7+AB7-AC7 | AE7: =MIN(AD7,MAX(0,$B7-((E$5<AC$5)*F7+(K$5<AC$5)*L7+(Q$5<AC$5)*R7+(W$5<AC$5)*X7+(AI$5<AC$5)*AJ7+(AO$5<AC$5)*AP7+(AU$5<AC$5)*AV7))) | AF7: =IF(AD7-AE7<0.005,0,AD7-AE7) | AG7: =MAX(0,Plan!C11) | AH7: =AG7*Plan!D11/100/12 | AI7: =MIN(Plan!E11,AG7+AH7) | AJ7: =AG7+AH7-AI7 | AK7: =MIN(AJ7,MAX(0,$B7-((E$5<AI$5)*F7+(K$5<AI$5)*L7+(Q$5<AI$5)*R7+(W$5<AI$5)*X7+(AC$5<AI$5)*AD7+(AO$5<AI$5)*AP7+(AU$5<AI$5)*AV7))) | AL7: =IF(AJ7-AK7<0.005,0,AJ7-AK7) | AM7: =MAX(0,Plan!C12) | AN7: =AM7*Plan!D12/100/12 | AO7: =MIN(Plan!E12,AM7+AN7) | AP7: =AM7+AN7-AO7 | AQ7: =MIN(AP7,MAX(0,$B7-((E$5<AO$5)*F7+(K$5<AO$5)*L7+(Q$5<AO$5)*R7+(W$5<AO$5)*X7+(AC$5<AO$5)*AD7+(AI$5<AO$5)*AJ7+(AU$5<AO$5)*AV7))) | AR7: =IF(AP7-AQ7<0.005,0,AP7-AQ7) | AS7: =MAX(0,Plan!C13) | AT7: =AS7*Plan!D13/100/12 | AU7: =MIN(Plan!E13,AS7+AT7) | AV7: =AS7+AT7-AU7 | AW7: =MIN(AV7,MAX(0,$B7-((E$5<AU$5)*F7+(K$5<AU$5)*L7+(Q$5<AU$5)*R7+(W$5<AU$5)*X7+(AC$5<AU$5)*AD7+(AI$5<AU$5)*AJ7+(AO$5<AU$5)*AP7))) | AX7: =IF(AV7-AW7<0.005,0,AV7-AW7) | BC7: =H7+N7+T7+Z7+AF7+AL7+AR7+AX7
A8: 2 | B8: =MAX(0,$B$3-(E8+K8+Q8+W8+AC8+AI8+AO8+AU8)) | C8: =H7 | D8: =C8*Plan!D6/100/12 | E8: =MIN(Plan!E6,C8+D8) | F8: =C8+D8-E8 | G8: =MIN(F8,MAX(0,$B8-((K$5<E$5)*L8+(Q$5<E$5)*R8+(W$5<E$5)*X8+(AC$5<E$5)*AD8+(AI$5<E$5)*AJ8+(AO$5<E$5)*AP8+(AU$5<E$5)*AV8))) | H8: =IF(F8-G8<0.005,0,F8-G8) | I8: =N7 | J8: =I8*Plan!D7/100/12 | K8: =MIN(Plan!E7,I8+J8) | L8: =I8+J8-K8 | M8: =MIN(L8,MAX(0,$B8-((E$5<K$5)*F8+(Q$5<K$5)*R8+(W$5<K$5)*X8+(AC$5<K$5)*AD8+(AI$5<K$5)*AJ8+(AO$5<K$5)*AP8+(AU$5<K$5)*AV8))) | N8: =IF(L8-M8<0.005,0,L8-M8) | O8: =T7 | P8: =O8*Plan!D8/100/12 | Q8: =MIN(Plan!E8,O8+P8) | R8: =O8+P8-Q8 | S8: =MIN(R8,MAX(0,$B8-((E$5<Q$5)*F8+(K$5<Q$5)*L8+(W$5<Q$5)*X8+(AC$5<Q$5)*AD8+(AI$5<Q$5)*AJ8+(AO$5<Q$5)*AP8+(AU$5<Q$5)*AV8))) | T8: =IF(R8-S8<0.005,0,R8-S8) | U8: =Z7 | V8: =U8*Plan!D9/100/12 | W8: =MIN(Plan!E9,U8+V8) | X8: =U8+V8-W8 | Y8: =MIN(X8,MAX(0,$B8-((E$5<W$5)*F8+(K$5<W$5)*L8+(Q$5<W$5)*R8+(AC$5<W$5)*AD8+(AI$5<W$5)*AJ8+(AO$5<W$5)*AP8+(AU$5<W$5)*AV8))) | Z8: =IF(X8-Y8<0.005,0,X8-Y8) | AA8: =AF7 | AB8: =AA8*Plan!D10/100/12 | AC8: =MIN(Plan!E10,AA8+AB8) | AD8: =AA8+AB8-AC8 | AE8: =MIN(AD8,MAX(0,$B8-((E$5<AC$5)*F8+(K$5<AC$5)*L8+(Q$5<AC$5)*R8+(W$5<AC$5)*X8+(AI$5<AC$5)*AJ8+(AO$5<AC$5)*AP8+(AU$5<AC$5)*AV8))) | AF8: =IF(AD8-AE8<0.005,0,AD8-AE8) | AG8: =AL7 | AH8: =AG8*Plan!D11/100/12 | AI8: =MIN(Plan!E11,AG8+AH8) | AJ8: =AG8+AH8-AI8 | AK8: =MIN(AJ8,MAX(0,$B8-((E$5<AI$5)*F8+(K$5<AI$5)*L8+(Q$5<AI$5)*R8+(W$5<AI$5)*X8+(AC$5<AI$5)*AD8+(AO$5<AI$5)*AP8+(AU$5<AI$5)*AV8))) | AL8: =IF(AJ8-AK8<0.005,0,AJ8-AK8) | AM8: =AR7 | AN8: =AM8*Plan!D12/100/12 | AO8: =MIN(Plan!E12,AM8+AN8) | AP8: =AM8+AN8-AO8 | AQ8: =MIN(AP8,MAX(0,$B8-((E$5<AO$5)*F8+(K$5<AO$5)*L8+(Q$5<AO$5)*R8+(W$5<AO$5)*X8+(AC$5<AO$5)*AD8+(AI$5<AO$5)*AJ8+(AU$5<AO$5)*AV8))) | AR8: =IF(AP8-AQ8<0.005,0,AP8-AQ8) | AS8: =AX7 | AT8: =AS8*Plan!D13/100/12 | AU8: =MIN(Plan!E13,AS8+AT8) | AV8: =AS8+AT8-AU8 | AW8: =MIN(AV8,MAX(0,$B8-((E$5<AU$5)*F8+(K$5<AU$5)*L8+(Q$5<AU$5)*R8+(W$5<AU$5)*X8+(AC$5<AU$5)*AD8+(AI$5<AU$5)*AJ8+(AO$5<AU$5)*AP8))) | AX8: =IF(AV8-AW8<0.005,0,AV8-AW8) | BC8: =H8+N8+T8+Z8+AF8+AL8+AR8+AX8
A9: 3 | B9: =MAX(0,$B$3-(E9+K9+Q9+W9+AC9+AI9+AO9+AU9)) | C9: =H8 | D9: =C9*Plan!D6/100/12 | E9: =MIN(Plan!E6,C9+D9) | F9: =C9+D9-E9 | G9: =MIN(F9,MAX(0,$B9-((K$5<E$5)*L9+(Q$5<E$5)*R9+(W$5<E$5)*X9+(AC$5<E$5)*AD9+(AI$5<E$5)*AJ9+(AO$5<E$5)*AP9+(AU$5<E$5)*AV9))) | H9: =IF(F9-G9<0.005,0,F9-G9) | I9: =N8 | J9: =I9*Plan!D7/100/12 | K9: =MIN(Plan!E7,I9+J9) | L9: =I9+J9-K9 | M9: =MIN(L9,MAX(0,$B9-((E$5<K$5)*F9+(Q$5<K$5)*R9+(W$5<K$5)*X9+(AC$5<K$5)*AD9+(AI$5<K$5)*AJ9+(AO$5<K$5)*AP9+(AU$5<K$5)*AV9))) | N9: =IF(L9-M9<0.005,0,L9-M9) | O9: =T8 | P9: =O9*Plan!D8/100/12 | Q9: =MIN(Plan!E8,O9+P9) | R9: =O9+P9-Q9 | S9: =MIN(R9,MAX(0,$B9-((E$5<Q$5)*F9+(K$5<Q$5)*L9+(W$5<Q$5)*X9+(AC$5<Q$5)*AD9+(AI$5<Q$5)*AJ9+(AO$5<Q$5)*AP9+(AU$5<Q$5)*AV9))) | T9: =IF(R9-S9<0.005,0,R9-S9) | U9: =Z8 | V9: =U9*Plan!D9/100/12 | W9: =MIN(Plan!E9,U9+V9) | X9: =U9+V9-W9 | Y9: =MIN(X9,MAX(0,$B9-((E$5<W$5)*F9+(K$5<W$5)*L9+(Q$5<W$5)*R9+(AC$5<W$5)*AD9+(AI$5<W$5)*AJ9+(AO$5<W$5)*AP9+(AU$5<W$5)*AV9))) | Z9: =IF(X9-Y9<0.005,0,X9-Y9) | AA9: =AF8 | AB9: =AA9*Plan!D10/100/12 | AC9: =MIN(Plan!E10,AA9+AB9) | AD9: =AA9+AB9-AC9 | AE9: =MIN(AD9,MAX(0,$B9-((E$5<AC$5)*F9+(K$5<AC$5)*L9+(Q$5<AC$5)*R9+(W$5<AC$5)*X9+(AI$5<AC$5)*AJ9+(AO$5<AC$5)*AP9+(AU$5<AC$5)*AV9))) | AF9: =IF(AD9-AE9<0.005,0,AD9-AE9) | AG9: =AL8 | AH9: =AG9*Plan!D11/100/12 | AI9: =MIN(Plan!E11,AG9+AH9) | AJ9: =AG9+AH9-AI9 | AK9: =MIN(AJ9,MAX(0,$B9-((E$5<AI$5)*F9+(K$5<AI$5)*L9+(Q$5<AI$5)*R9+(W$5<AI$5)*X9+(AC$5<AI$5)*AD9+(AO$5<AI$5)*AP9+(AU$5<AI$5)*AV9))) | AL9: =IF(AJ9-AK9<0.005,0,AJ9-AK9) | AM9: =AR8 | AN9: =AM9*Plan!D12/100/12 | AO9: =MIN(Plan!E12,AM9+AN9) | AP9: =AM9+AN9-AO9 | AQ9: =MIN(AP9,MAX(0,$B9-((E$5<AO$5)*F9+(K$5<AO$5)*L9+(Q$5<AO$5)*R9+(W$5<AO$5)*X9+(AC$5<AO$5)*AD9+(AI$5<AO$5)*AJ9+(AU$5<AO$5)*AV9))) | AR9: =IF(AP9-AQ9<0.005,0,AP9-AQ9) | AS9: =AX8 | AT9: =AS9*Plan!D13/100/12 | AU9: =MIN(Plan!E13,AS9+AT9) | AV9: =AS9+AT9-AU9 | AW9: =MIN(AV9,MAX(0,$B9-((E$5<AU$5)*F9+(K$5<AU$5)*L9+(Q$5<AU$5)*R9+(W$5<AU$5)*X9+(AC$5<AU$5)*AD9+(AI$5<AU$5)*AJ9+(AO$5<AU$5)*AP9))) | AX9: =IF(AV9-AW9<0.005,0,AV9-AW9) | BC9: =H9+N9+T9+Z9+AF9+AL9+AR9+AX9
A10: 4 | B10: =MAX(0,$B$3-(E10+K10+Q10+W10+AC10+AI10+AO10+AU10)) | C10: =H9 | D10: =C10*Plan!D6/100/12 | E10: =MIN(Plan!E6,C10+D10) | F10: =C10+D10-E10 | G10: =MIN(F10,MAX(0,$B10-((K$5<E$5)*L10+(Q$5<E$5)*R10+(W$5<E$5)*X10+(AC$5<E$5)*AD10+(AI$5<E$5)*AJ10+(AO$5<E$5)*AP10+(AU$5<E$5)*AV10))) | H10: =IF(F10-G10<0.005,0,F10-G10) | I10: =N9 | J10: =I10*Plan!D7/100/12 | K10: =MIN(Plan!E7,I10+J10) | L10: =I10+J10-K10 | M10: =MIN(L10,MAX(0,$B10-((E$5<K$5)*F10+(Q$5<K$5)*R10+(W$5<K$5)*X10+(AC$5<K$5)*AD10+(AI$5<K$5)*AJ10+(AO$5<K$5)*AP10+(AU$5<K$5)*AV10))) | N10: =IF(L10-M10<0.005,0,L10-M10) | O10: =T9 | P10: =O10*Plan!D8/100/12 | Q10: =MIN(Plan!E8,O10+P10) | R10: =O10+P10-Q10 | S10: =MIN(R10,MAX(0,$B10-((E$5<Q$5)*F10+(K$5<Q$5)*L10+(W$5<Q$5)*X10+(AC$5<Q$5)*AD10+(AI$5<Q$5)*AJ10+(AO$5<Q$5)*AP10+(AU$5<Q$5)*AV10))) | T10: =IF(R10-S10<0.005,0,R10-S10) | U10: =Z9 | V10: =U10*Plan!D9/100/12 | W10: =MIN(Plan!E9,U10+V10) | X10: =U10+V10-W10 | Y10: =MIN(X10,MAX(0,$B10-((E$5<W$5)*F10+(K$5<W$5)*L10+(Q$5<W$5)*R10+(AC$5<W$5)*AD10+(AI$5<W$5)*AJ10+(AO$5<W$5)*AP10+(AU$5<W$5)*AV10))) | Z10: =IF(X10-Y10<0.005,0,X10-Y10) | AA10: =AF9 | AB10: =AA10*Plan!D10/100/12 | AC10: =MIN(Plan!E10,AA10+AB10) | AD10: =AA10+AB10-AC10 | AE10: =MIN(AD10,MAX(0,$B10-((E$5<AC$5)*F10+(K$5<AC$5)*L10+(Q$5<AC$5)*R10+(W$5<AC$5)*X10+(AI$5<AC$5)*AJ10+(AO$5<AC$5)*AP10+(AU$5<AC$5)*AV10))) | AF10: =IF(AD10-AE10<0.005,0,AD10-AE10) | AG10: =AL9 | AH10: =AG10*Plan!D11/100/12 | AI10: =MIN(Plan!E11,AG10+AH10) | AJ10: =AG10+AH10-AI10 | AK10: =MIN(AJ10,MAX(0,$B10-((E$5<AI$5)*F10+(K$5<AI$5)*L10+(Q$5<AI$5)*R10+(W$5<AI$5)*X10+(AC$5<AI$5)*AD10+(AO$5<AI$5)*AP10+(AU$5<AI$5)*AV10))) | AL10: =IF(AJ10-AK10<0.005,0,AJ10-AK10) | AM10: =AR9 | AN10: =AM10*Plan!D12/100/12 | AO10: =MIN(Plan!E12,AM10+AN10) | AP10: =AM10+AN10-AO10 | AQ10: =MIN(AP10,MAX(0,$B10-((E$5<AO$5)*F10+(K$5<AO$5)*L10+(Q$5<AO$5)*R10+(W$5<AO$5)*X10+(AC$5<AO$5)*AD10+(AI$5<AO$5)*AJ10+(AU$5<AO$5)*AV10))) | AR10: =IF(AP10-AQ10<0.005,0,AP10-AQ10) | AS10: =AX9 | AT10: =AS10*Plan!D13/100/12 | AU10: =MIN(Plan!E13,AS10+AT10) | AV10: =AS10+AT10-AU10 | AW10: =MIN(AV10,MAX(0,$B10-((E$5<AU$5)*F10+(K$5<AU$5)*L10+(Q$5<AU$5)*R10+(W$5<AU$5)*X10+(AC$5<AU$5)*AD10+(AI$5<AU$5)*AJ10+(AO$5<AU$5)*AP10))) | AX10: =IF(AV10-AW10<0.005,0,AV10-AW10) | BC10: =H10+N10+T10+Z10+AF10+AL10+AR10+AX10
A11: 5 | B11: =MAX(0,$B$3-(E11+K11+Q11+W11+AC11+AI11+AO11+AU11)) | C11: =H10 | D11: =C11*Plan!D6/100/12 | E11: =MIN(Plan!E6,C11+D11) | F11: =C11+D11-E11 | G11: =MIN(F11,MAX(0,$B11-((K$5<E$5)*L11+(Q$5<E$5)*R11+(W$5<E$5)*X11+(AC$5<E$5)*AD11+(AI$5<E$5)*AJ11+(AO$5<E$5)*AP11+(AU$5<E$5)*AV11))) | H11: =IF(F11-G11<0.005,0,F11-G11) | I11: =N10 | J11: =I11*Plan!D7/100/12 | K11: =MIN(Plan!E7,I11+J11) | L11: =I11+J11-K11 | M11: =MIN(L11,MAX(0,$B11-((E$5<K$5)*F11+(Q$5<K$5)*R11+(W$5<K$5)*X11+(AC$5<K$5)*AD11+(AI$5<K$5)*AJ11+(AO$5<K$5)*AP11+(AU$5<K$5)*AV11))) | N11: =IF(L11-M11<0.005,0,L11-M11) | O11: =T10 | P11: =O11*Plan!D8/100/12 | Q11: =MIN(Plan!E8,O11+P11) | R11: =O11+P11-Q11 | S11: =MIN(R11,MAX(0,$B11-((E$5<Q$5)*F11+(K$5<Q$5)*L11+(W$5<Q$5)*X11+(AC$5<Q$5)*AD11+(AI$5<Q$5)*AJ11+(AO$5<Q$5)*AP11+(AU$5<Q$5)*AV11))) | T11: =IF(R11-S11<0.005,0,R11-S11) | U11: =Z10 | V11: =U11*Plan!D9/100/12 | W11: =MIN(Plan!E9,U11+V11) | X11: =U11+V11-W11 | Y11: =MIN(X11,MAX(0,$B11-((E$5<W$5)*F11+(K$5<W$5)*L11+(Q$5<W$5)*R11+(AC$5<W$5)*AD11+(AI$5<W$5)*AJ11+(AO$5<W$5)*AP11+(AU$5<W$5)*AV11))) | Z11: =IF(X11-Y11<0.005,0,X11-Y11) | AA11: =AF10 | AB11: =AA11*Plan!D10/100/12 | AC11: =MIN(Plan!E10,AA11+AB11) | AD11: =AA11+AB11-AC11 | AE11: =MIN(AD11,MAX(0,$B11-((E$5<AC$5)*F11+(K$5<AC$5)*L11+(Q$5<AC$5)*R11+(W$5<AC$5)*X11+(AI$5<AC$5)*AJ11+(AO$5<AC$5)*AP11+(AU$5<AC$5)*AV11))) | AF11: =IF(AD11-AE11<0.005,0,AD11-AE11) | AG11: =AL10 | AH11: =AG11*Plan!D11/100/12 | AI11: =MIN(Plan!E11,AG11+AH11) | AJ11: =AG11+AH11-AI11 | AK11: =MIN(AJ11,MAX(0,$B11-((E$5<AI$5)*F11+(K$5<AI$5)*L11+(Q$5<AI$5)*R11+(W$5<AI$5)*X11+(AC$5<AI$5)*AD11+(AO$5<AI$5)*AP11+(AU$5<AI$5)*AV11))) | AL11: =IF(AJ11-AK11<0.005,0,AJ11-AK11) | AM11: =AR10 | AN11: =AM11*Plan!D12/100/12 | AO11: =MIN(Plan!E12,AM11+AN11) | AP11: =AM11+AN11-AO11 | AQ11: =MIN(AP11,MAX(0,$B11-((E$5<AO$5)*F11+(K$5<AO$5)*L11+(Q$5<AO$5)*R11+(W$5<AO$5)*X11+(AC$5<AO$5)*AD11+(AI$5<AO$5)*AJ11+(AU$5<AO$5)*AV11))) | AR11: =IF(AP11-AQ11<0.005,0,AP11-AQ11) | AS11: =AX10 | AT11: =AS11*Plan!D13/100/12 | AU11: =MIN(Plan!E13,AS11+AT11) | AV11: =AS11+AT11-AU11 | AW11: =MIN(AV11,MAX(0,$B11-((E$5<AU$5)*F11+(K$5<AU$5)*L11+(Q$5<AU$5)*R11+(W$5<AU$5)*X11+(AC$5<AU$5)*AD11+(AI$5<AU$5)*AJ11+(AO$5<AU$5)*AP11))) | AX11: =IF(AV11-AW11<0.005,0,AV11-AW11) | BC11: =H11+N11+T11+Z11+AF11+AL11+AR11+AX11
A12: 6 | B12: =MAX(0,$B$3-(E12+K12+Q12+W12+AC12+AI12+AO12+AU12)) | C12: =H11 | D12: =C12*Plan!D6/100/12 | E12: =MIN(Plan!E6,C12+D12) | F12: =C12+D12-E12 | G12: =MIN(F12,MAX(0,$B12-((K$5<E$5)*L12+(Q$5<E$5)*R12+(W$5<E$5)*X12+(AC$5<E$5)*AD12+(AI$5<E$5)*AJ12+(AO$5<E$5)*AP12+(AU$5<E$5)*AV12))) | H12: =IF(F12-G12<0.005,0,F12-G12) | I12: =N11 | J12: =I12*Plan!D7/100/12 | K12: =MIN(Plan!E7,I12+J12) | L12: =I12+J12-K12 | M12: =MIN(L12,MAX(0,$B12-((E$5<K$5)*F12+(Q$5<K$5)*R12+(W$5<K$5)*X12+(AC$5<K$5)*AD12+(AI$5<K$5)*AJ12+(AO$5<K$5)*AP12+(AU$5<K$5)*AV12))) | N12: =IF(L12-M12<0.005,0,L12-M12) | O12: =T11 | P12: =O12*Plan!D8/100/12 | Q12: =MIN(Plan!E8,O12+P12) | R12: =O12+P12-Q12 | S12: =MIN(R12,MAX(0,$B12-((E$5<Q$5)*F12+(K$5<Q$5)*L12+(W$5<Q$5)*X12+(AC$5<Q$5)*AD12+(AI$5<Q$5)*AJ12+(AO$5<Q$5)*AP12+(AU$5<Q$5)*AV12))) | T12: =IF(R12-S12<0.005,0,R12-S12) | U12: =Z11 | V12: =U12*Plan!D9/100/12 | W12: =MIN(Plan!E9,U12+V12) | X12: =U12+V12-W12 | Y12: =MIN(X12,MAX(0,$B12-((E$5<W$5)*F12+(K$5<W$5)*L12+(Q$5<W$5)*R12+(AC$5<W$5)*AD12+(AI$5<W$5)*AJ12+(AO$5<W$5)*AP12+(AU$5<W$5)*AV12))) | Z12: =IF(X12-Y12<0.005,0,X12-Y12) | AA12: =AF11 | AB12: =AA12*Plan!D10/100/12 | AC12: =MIN(Plan!E10,AA12+AB12) | AD12: =AA12+AB12-AC12 | AE12: =MIN(AD12,MAX(0,$B12-((E$5<AC$5)*F12+(K$5<AC$5)*L12+(Q$5<AC$5)*R12+(W$5<AC$5)*X12+(AI$5<AC$5)*AJ12+(AO$5<AC$5)*AP12+(AU$5<AC$5)*AV12))) | AF12: =IF(AD12-AE12<0.005,0,AD12-AE12) | AG12: =AL11 | AH12: =AG12*Plan!D11/100/12 | AI12: =MIN(Plan!E11,AG12+AH12) | AJ12: =AG12+AH12-AI12 | AK12: =MIN(AJ12,MAX(0,$B12-((E$5<AI$5)*F12+(K$5<AI$5)*L12+(Q$5<AI$5)*R12+(W$5<AI$5)*X12+(AC$5<AI$5)*AD12+(AO$5<AI$5)*AP12+(AU$5<AI$5)*AV12))) | AL12: =IF(AJ12-AK12<0.005,0,AJ12-AK12) | AM12: =AR11 | AN12: =AM12*Plan!D12/100/12 | AO12: =MIN(Plan!E12,AM12+AN12) | AP12: =AM12+AN12-AO12 | AQ12: =MIN(AP12,MAX(0,$B12-((E$5<AO$5)*F12+(K$5<AO$5)*L12+(Q$5<AO$5)*R12+(W$5<AO$5)*X12+(AC$5<AO$5)*AD12+(AI$5<AO$5)*AJ12+(AU$5<AO$5)*AV12))) | AR12: =IF(AP12-AQ12<0.005,0,AP12-AQ12) | AS12: =AX11 | AT12: =AS12*Plan!D13/100/12 | AU12: =MIN(Plan!E13,AS12+AT12) | AV12: =AS12+AT12-AU12 | AW12: =MIN(AV12,MAX(0,$B12-((E$5<AU$5)*F12+(K$5<AU$5)*L12+(Q$5<AU$5)*R12+(W$5<AU$5)*X12+(AC$5<AU$5)*AD12+(AI$5<AU$5)*AJ12+(AO$5<AU$5)*AP12))) | AX12: =IF(AV12-AW12<0.005,0,AV12-AW12) | BC12: =H12+N12+T12+Z12+AF12+AL12+AR12+AX12
A13: 7 | B13: =MAX(0,$B$3-(E13+K13+Q13+W13+AC13+AI13+AO13+AU13)) | C13: =H12 | D13: =C13*Plan!D6/100/12 | E13: =MIN(Plan!E6,C13+D13) | F13: =C13+D13-E13 | G13: =MIN(F13,MAX(0,$B13-((K$5<E$5)*L13+(Q$5<E$5)*R13+(W$5<E$5)*X13+(AC$5<E$5)*AD13+(AI$5<E$5)*AJ13+(AO$5<E$5)*AP13+(AU$5<E$5)*AV13))) | H13: =IF(F13-G13<0.005,0,F13-G13) | I13: =N12 | J13: =I13*Plan!D7/100/12 | K13: =MIN(Plan!E7,I13+J13) | L13: =I13+J13-K13 | M13: =MIN(L13,MAX(0,$B13-((E$5<K$5)*F13+(Q$5<K$5)*R13+(W$5<K$5)*X13+(AC$5<K$5)*AD13+(AI$5<K$5)*AJ13+(AO$5<K$5)*AP13+(AU$5<K$5)*AV13))) | N13: =IF(L13-M13<0.005,0,L13-M13) | O13: =T12 | P13: =O13*Plan!D8/100/12 | Q13: =MIN(Plan!E8,O13+P13) | R13: =O13+P13-Q13 | S13: =MIN(R13,MAX(0,$B13-((E$5<Q$5)*F13+(K$5<Q$5)*L13+(W$5<Q$5)*X13+(AC$5<Q$5)*AD13+(AI$5<Q$5)*AJ13+(AO$5<Q$5)*AP13+(AU$5<Q$5)*AV13))) | T13: =IF(R13-S13<0.005,0,R13-S13) | U13: =Z12 | V13: =U13*Plan!D9/100/12 | W13: =MIN(Plan!E9,U13+V13) | X13: =U13+V13-W13 | Y13: =MIN(X13,MAX(0,$B13-((E$5<W$5)*F13+(K$5<W$5)*L13+(Q$5<W$5)*R13+(AC$5<W$5)*AD13+(AI$5<W$5)*AJ13+(AO$5<W$5)*AP13+(AU$5<W$5)*AV13))) | Z13: =IF(X13-Y13<0.005,0,X13-Y13) | AA13: =AF12 | AB13: =AA13*Plan!D10/100/12 | AC13: =MIN(Plan!E10,AA13+AB13) | AD13: =AA13+AB13-AC13 | AE13: =MIN(AD13,MAX(0,$B13-((E$5<AC$5)*F13+(K$5<AC$5)*L13+(Q$5<AC$5)*R13+(W$5<AC$5)*X13+(AI$5<AC$5)*AJ13+(AO$5<AC$5)*AP13+(AU$5<AC$5)*AV13))) | AF13: =IF(AD13-AE13<0.005,0,AD13-AE13) | AG13: =AL12 | AH13: =AG13*Plan!D11/100/12 | AI13: =MIN(Plan!E11,AG13+AH13) | AJ13: =AG13+AH13-AI13 | AK13: =MIN(AJ13,MAX(0,$B13-((E$5<AI$5)*F13+(K$5<AI$5)*L13+(Q$5<AI$5)*R13+(W$5<AI$5)*X13+(AC$5<AI$5)*AD13+(AO$5<AI$5)*AP13+(AU$5<AI$5)*AV13))) | AL13: =IF(AJ13-AK13<0.005,0,AJ13-AK13) | AM13: =AR12 | AN13: =AM13*Plan!D12/100/12 | AO13: =MIN(Plan!E12,AM13+AN13) | AP13: =AM13+AN13-AO13 | AQ13: =MIN(AP13,MAX(0,$B13-((E$5<AO$5)*F13+(K$5<AO$5)*L13+(Q$5<AO$5)*R13+(W$5<AO$5)*X13+(AC$5<AO$5)*AD13+(AI$5<AO$5)*AJ13+(AU$5<AO$5)*AV13))) | AR13: =IF(AP13-AQ13<0.005,0,AP13-AQ13) | AS13: =AX12 | AT13: =AS13*Plan!D13/100/12 | AU13: =MIN(Plan!E13,AS13+AT13) | AV13: =AS13+AT13-AU13 | AW13: =MIN(AV13,MAX(0,$B13-((E$5<AU$5)*F13+(K$5<AU$5)*L13+(Q$5<AU$5)*R13+(W$5<AU$5)*X13+(AC$5<AU$5)*AD13+(AI$5<AU$5)*AJ13+(AO$5<AU$5)*AP13))) | AX13: =IF(AV13-AW13<0.005,0,AV13-AW13) | BC13: =H13+N13+T13+Z13+AF13+AL13+AR13+AX13
A14: 8 | B14: =MAX(0,$B$3-(E14+K14+Q14+W14+AC14+AI14+AO14+AU14)) | C14: =H13 | D14: =C14*Plan!D6/100/12 | E14: =MIN(Plan!E6,C14+D14) | F14: =C14+D14-E14 | G14: =MIN(F14,MAX(0,$B14-((K$5<E$5)*L14+(Q$5<E$5)*R14+(W$5<E$5)*X14+(AC$5<E$5)*AD14+(AI$5<E$5)*AJ14+(AO$5<E$5)*AP14+(AU$5<E$5)*AV14))) | H14: =IF(F14-G14<0.005,0,F14-G14) | I14: =N13 | J14: =I14*Plan!D7/100/12 | K14: =MIN(Plan!E7,I14+J14) | L14: =I14+J14-K14 | M14: =MIN(L14,MAX(0,$B14-((E$5<K$5)*F14+(Q$5<K$5)*R14+(W$5<K$5)*X14+(AC$5<K$5)*AD14+(AI$5<K$5)*AJ14+(AO$5<K$5)*AP14+(AU$5<K$5)*AV14))) | N14: =IF(L14-M14<0.005,0,L14-M14) | O14: =T13 | P14: =O14*Plan!D8/100/12 | Q14: =MIN(Plan!E8,O14+P14) | R14: =O14+P14-Q14 | S14: =MIN(R14,MAX(0,$B14-((E$5<Q$5)*F14+(K$5<Q$5)*L14+(W$5<Q$5)*X14+(AC$5<Q$5)*AD14+(AI$5<Q$5)*AJ14+(AO$5<Q$5)*AP14+(AU$5<Q$5)*AV14))) | T14: =IF(R14-S14<0.005,0,R14-S14) | U14: =Z13 | V14: =U14*Plan!D9/100/12 | W14: =MIN(Plan!E9,U14+V14) | X14: =U14+V14-W14 | Y14: =MIN(X14,MAX(0,$B14-((E$5<W$5)*F14+(K$5<W$5)*L14+(Q$5<W$5)*R14+(AC$5<W$5)*AD14+(AI$5<W$5)*AJ14+(AO$5<W$5)*AP14+(AU$5<W$5)*AV14))) | Z14: =IF(X14-Y14<0.005,0,X14-Y14) | AA14: =AF13 | AB14: =AA14*Plan!D10/100/12 | AC14: =MIN(Plan!E10,AA14+AB14) | AD14: =AA14+AB14-AC14 | AE14: =MIN(AD14,MAX(0,$B14-((E$5<AC$5)*F14+(K$5<AC$5)*L14+(Q$5<AC$5)*R14+(W$5<AC$5)*X14+(AI$5<AC$5)*AJ14+(AO$5<AC$5)*AP14+(AU$5<AC$5)*AV14))) | AF14: =IF(AD14-AE14<0.005,0,AD14-AE14) | AG14: =AL13 | AH14: =AG14*Plan!D11/100/12 | AI14: =MIN(Plan!E11,AG14+AH14) | AJ14: =AG14+AH14-AI14 | AK14: =MIN(AJ14,MAX(0,$B14-((E$5<AI$5)*F14+(K$5<AI$5)*L14+(Q$5<AI$5)*R14+(W$5<AI$5)*X14+(AC$5<AI$5)*AD14+(AO$5<AI$5)*AP14+(AU$5<AI$5)*AV14))) | AL14: =IF(AJ14-AK14<0.005,0,AJ14-AK14) | AM14: =AR13 | AN14: =AM14*Plan!D12/100/12 | AO14: =MIN(Plan!E12,AM14+AN14) | AP14: =AM14+AN14-AO14 | AQ14: =MIN(AP14,MAX(0,$B14-((E$5<AO$5)*F14+(K$5<AO$5)*L14+(Q$5<AO$5)*R14+(W$5<AO$5)*X14+(AC$5<AO$5)*AD14+(AI$5<AO$5)*AJ14+(AU$5<AO$5)*AV14))) | AR14: =IF(AP14-AQ14<0.005,0,AP14-AQ14) | AS14: =AX13 | AT14: =AS14*Plan!D13/100/12 | AU14: =MIN(Plan!E13,AS14+AT14) | AV14: =AS14+AT14-AU14 | AW14: =MIN(AV14,MAX(0,$B14-((E$5<AU$5)*F14+(K$5<AU$5)*L14+(Q$5<AU$5)*R14+(W$5<AU$5)*X14+(AC$5<AU$5)*AD14+(AI$5<AU$5)*AJ14+(AO$5<AU$5)*AP14))) | AX14: =IF(AV14-AW14<0.005,0,AV14-AW14) | BC14: =H14+N14+T14+Z14+AF14+AL14+AR14+AX14
A15: 9 | B15: =MAX(0,$B$3-(E15+K15+Q15+W15+AC15+AI15+AO15+AU15)) | C15: =H14 | D15: =C15*Plan!D6/100/12 | E15: =MIN(Plan!E6,C15+D15) | F15: =C15+D15-E15 | G15: =MIN(F15,MAX(0,$B15-((K$5<E$5)*L15+(Q$5<E$5)*R15+(W$5<E$5)*X15+(AC$5<E$5)*AD15+(AI$5<E$5)*AJ15+(AO$5<E$5)*AP15+(AU$5<E$5)*AV15))) | H15: =IF(F15-G15<0.005,0,F15-G15) | I15: =N14 | J15: =I15*Plan!D7/100/12 | K15: =MIN(Plan!E7,I15+J15) | L15: =I15+J15-K15 | M15: =MIN(L15,MAX(0,$B15-((E$5<K$5)*F15+(Q$5<K$5)*R15+(W$5<K$5)*X15+(AC$5<K$5)*AD15+(AI$5<K$5)*AJ15+(AO$5<K$5)*AP15+(AU$5<K$5)*AV15))) | N15: =IF(L15-M15<0.005,0,L15-M15) | O15: =T14 | P15: =O15*Plan!D8/100/12 | Q15: =MIN(Plan!E8,O15+P15) | R15: =O15+P15-Q15 | S15: =MIN(R15,MAX(0,$B15-((E$5<Q$5)*F15+(K$5<Q$5)*L15+(W$5<Q$5)*X15+(AC$5<Q$5)*AD15+(AI$5<Q$5)*AJ15+(AO$5<Q$5)*AP15+(AU$5<Q$5)*AV15))) | T15: =IF(R15-S15<0.005,0,R15-S15) | U15: =Z14 | V15: =U15*Plan!D9/100/12 | W15: =MIN(Plan!E9,U15+V15) | X15: =U15+V15-W15 | Y15: =MIN(X15,MAX(0,$B15-((E$5<W$5)*F15+(K$5<W$5)*L15+(Q$5<W$5)*R15+(AC$5<W$5)*AD15+(AI$5<W$5)*AJ15+(AO$5<W$5)*AP15+(AU$5<W$5)*AV15))) | Z15: =IF(X15-Y15<0.005,0,X15-Y15) | AA15: =AF14 | AB15: =AA15*Plan!D10/100/12 | AC15: =MIN(Plan!E10,AA15+AB15) | AD15: =AA15+AB15-AC15 | AE15: =MIN(AD15,MAX(0,$B15-((E$5<AC$5)*F15+(K$5<AC$5)*L15+(Q$5<AC$5)*R15+(W$5<AC$5)*X15+(AI$5<AC$5)*AJ15+(AO$5<AC$5)*AP15+(AU$5<AC$5)*AV15))) | AF15: =IF(AD15-AE15<0.005,0,AD15-AE15) | AG15: =AL14 | AH15: =AG15*Plan!D11/100/12 | AI15: =MIN(Plan!E11,AG15+AH15) | AJ15: =AG15+AH15-AI15 | AK15: =MIN(AJ15,MAX(0,$B15-((E$5<AI$5)*F15+(K$5<AI$5)*L15+(Q$5<AI$5)*R15+(W$5<AI$5)*X15+(AC$5<AI$5)*AD15+(AO$5<AI$5)*AP15+(AU$5<AI$5)*AV15))) | AL15: =IF(AJ15-AK15<0.005,0,AJ15-AK15) | AM15: =AR14 | AN15: =AM15*Plan!D12/100/12 | AO15: =MIN(Plan!E12,AM15+AN15) | AP15: =AM15+AN15-AO15 | AQ15: =MIN(AP15,MAX(0,$B15-((E$5<AO$5)*F15+(K$5<AO$5)*L15+(Q$5<AO$5)*R15+(W$5<AO$5)*X15+(AC$5<AO$5)*AD15+(AI$5<AO$5)*AJ15+(AU$5<AO$5)*AV15))) | AR15: =IF(AP15-AQ15<0.005,0,AP15-AQ15) | AS15: =AX14 | AT15: =AS15*Plan!D13/100/12 | AU15: =MIN(Plan!E13,AS15+AT15) | AV15: =AS15+AT15-AU15 | AW15: =MIN(AV15,MAX(0,$B15-((E$5<AU$5)*F15+(K$5<AU$5)*L15+(Q$5<AU$5)*R15+(W$5<AU$5)*X15+(AC$5<AU$5)*AD15+(AI$5<AU$5)*AJ15+(AO$5<AU$5)*AP15))) | AX15: =IF(AV15-AW15<0.005,0,AV15-AW15) | BC15: =H15+N15+T15+Z15+AF15+AL15+AR15+AX15
A16: 10 | B16: =MAX(0,$B$3-(E16+K16+Q16+W16+AC16+AI16+AO16+AU16)) | C16: =H15 | D16: =C16*Plan!D6/100/12 | E16: =MIN(Plan!E6,C16+D16) | F16: =C16+D16-E16 | G16: =MIN(F16,MAX(0,$B16-((K$5<E$5)*L16+(Q$5<E$5)*R16+(W$5<E$5)*X16+(AC$5<E$5)*AD16+(AI$5<E$5)*AJ16+(AO$5<E$5)*AP16+(AU$5<E$5)*AV16))) | H16: =IF(F16-G16<0.005,0,F16-G16) | I16: =N15 | J16: =I16*Plan!D7/100/12 | K16: =MIN(Plan!E7,I16+J16) | L16: =I16+J16-K16 | M16: =MIN(L16,MAX(0,$B16-((E$5<K$5)*F16+(Q$5<K$5)*R16+(W$5<K$5)*X16+(AC$5<K$5)*AD16+(AI$5<K$5)*AJ16+(AO$5<K$5)*AP16+(AU$5<K$5)*AV16))) | N16: =IF(L16-M16<0.005,0,L16-M16) | O16: =T15 | P16: =O16*Plan!D8/100/12 | Q16: =MIN(Plan!E8,O16+P16) | R16: =O16+P16-Q16 | S16: =MIN(R16,MAX(0,$B16-((E$5<Q$5)*F16+(K$5<Q$5)*L16+(W$5<Q$5)*X16+(AC$5<Q$5)*AD16+(AI$5<Q$5)*AJ16+(AO$5<Q$5)*AP16+(AU$5<Q$5)*AV16))) | T16: =IF(R16-S16<0.005,0,R16-S16) | U16: =Z15 | V16: =U16*Plan!D9/100/12 | W16: =MIN(Plan!E9,U16+V16) | X16: =U16+V16-W16 | Y16: =MIN(X16,MAX(0,$B16-((E$5<W$5)*F16+(K$5<W$5)*L16+(Q$5<W$5)*R16+(AC$5<W$5)*AD16+(AI$5<W$5)*AJ16+(AO$5<W$5)*AP16+(AU$5<W$5)*AV16))) | Z16: =IF(X16-Y16<0.005,0,X16-Y16) | AA16: =AF15 | AB16: =AA16*Plan!D10/100/12 | AC16: =MIN(Plan!E10,AA16+AB16) | AD16: =AA16+AB16-AC16 | AE16: =MIN(AD16,MAX(0,$B16-((E$5<AC$5)*F16+(K$5<AC$5)*L16+(Q$5<AC$5)*R16+(W$5<AC$5)*X16+(AI$5<AC$5)*AJ16+(AO$5<AC$5)*AP16+(AU$5<AC$5)*AV16))) | AF16: =IF(AD16-AE16<0.005,0,AD16-AE16) | AG16: =AL15 | AH16: =AG16*Plan!D11/100/12 | AI16: =MIN(Plan!E11,AG16+AH16) | AJ16: =AG16+AH16-AI16 | AK16: =MIN(AJ16,MAX(0,$B16-((E$5<AI$5)*F16+(K$5<AI$5)*L16+(Q$5<AI$5)*R16+(W$5<AI$5)*X16+(AC$5<AI$5)*AD16+(AO$5<AI$5)*AP16+(AU$5<AI$5)*AV16))) | AL16: =IF(AJ16-AK16<0.005,0,AJ16-AK16) | AM16: =AR15 | AN16: =AM16*Plan!D12/100/12 | AO16: =MIN(Plan!E12,AM16+AN16) | AP16: =AM16+AN16-AO16 | AQ16: =MIN(AP16,MAX(0,$B16-((E$5<AO$5)*F16+(K$5<AO$5)*L16+(Q$5<AO$5)*R16+(W$5<AO$5)*X16+(AC$5<AO$5)*AD16+(AI$5<AO$5)*AJ16+(AU$5<AO$5)*AV16))) | AR16: =IF(AP16-AQ16<0.005,0,AP16-AQ16) | AS16: =AX15 | AT16: =AS16*Plan!D13/100/12 | AU16: =MIN(Plan!E13,AS16+AT16) | AV16: =AS16+AT16-AU16 | AW16: =MIN(AV16,MAX(0,$B16-((E$5<AU$5)*F16+(K$5<AU$5)*L16+(Q$5<AU$5)*R16+(W$5<AU$5)*X16+(AC$5<AU$5)*AD16+(AI$5<AU$5)*AJ16+(AO$5<AU$5)*AP16))) | AX16: =IF(AV16-AW16<0.005,0,AV16-AW16) | BC16: =H16+N16+T16+Z16+AF16+AL16+AR16+AX16
A17: 11 | B17: =MAX(0,$B$3-(E17+K17+Q17+W17+AC17+AI17+AO17+AU17)) | C17: =H16 | D17: =C17*Plan!D6/100/12 | E17: =MIN(Plan!E6,C17+D17) | F17: =C17+D17-E17 | G17: =MIN(F17,MAX(0,$B17-((K$5<E$5)*L17+(Q$5<E$5)*R17+(W$5<E$5)*X17+(AC$5<E$5)*AD17+(AI$5<E$5)*AJ17+(AO$5<E$5)*AP17+(AU$5<E$5)*AV17))) | H17: =IF(F17-G17<0.005,0,F17-G17) | I17: =N16 | J17: =I17*Plan!D7/100/12 | K17: =MIN(Plan!E7,I17+J17) | L17: =I17+J17-K17 | M17: =MIN(L17,MAX(0,$B17-((E$5<K$5)*F17+(Q$5<K$5)*R17+(W$5<K$5)*X17+(AC$5<K$5)*AD17+(AI$5<K$5)*AJ17+(AO$5<K$5)*AP17+(AU$5<K$5)*AV17))) | N17: =IF(L17-M17<0.005,0,L17-M17) | O17: =T16 | P17: =O17*Plan!D8/100/12 | Q17: =MIN(Plan!E8,O17+P17) | R17: =O17+P17-Q17 | S17: =MIN(R17,MAX(0,$B17-((E$5<Q$5)*F17+(K$5<Q$5)*L17+(W$5<Q$5)*X17+(AC$5<Q$5)*AD17+(AI$5<Q$5)*AJ17+(AO$5<Q$5)*AP17+(AU$5<Q$5)*AV17))) | T17: =IF(R17-S17<0.005,0,R17-S17) | U17: =Z16 | V17: =U17*Plan!D9/100/12 | W17: =MIN(Plan!E9,U17+V17) | X17: =U17+V17-W17 | Y17: =MIN(X17,MAX(0,$B17-((E$5<W$5)*F17+(K$5<W$5)*L17+(Q$5<W$5)*R17+(AC$5<W$5)*AD17+(AI$5<W$5)*AJ17+(AO$5<W$5)*AP17+(AU$5<W$5)*AV17))) | Z17: =IF(X17-Y17<0.005,0,X17-Y17) | AA17: =AF16 | AB17: =AA17*Plan!D10/100/12 | AC17: =MIN(Plan!E10,AA17+AB17) | AD17: =AA17+AB17-AC17 | AE17: =MIN(AD17,MAX(0,$B17-((E$5<AC$5)*F17+(K$5<AC$5)*L17+(Q$5<AC$5)*R17+(W$5<AC$5)*X17+(AI$5<AC$5)*AJ17+(AO$5<AC$5)*AP17+(AU$5<AC$5)*AV17))) | AF17: =IF(AD17-AE17<0.005,0,AD17-AE17) | AG17: =AL16 | AH17: =AG17*Plan!D11/100/12 | AI17: =MIN(Plan!E11,AG17+AH17) | AJ17: =AG17+AH17-AI17 | AK17: =MIN(AJ17,MAX(0,$B17-((E$5<AI$5)*F17+(K$5<AI$5)*L17+(Q$5<AI$5)*R17+(W$5<AI$5)*X17+(AC$5<AI$5)*AD17+(AO$5<AI$5)*AP17+(AU$5<AI$5)*AV17))) | AL17: =IF(AJ17-AK17<0.005,0,AJ17-AK17) | AM17: =AR16 | AN17: =AM17*Plan!D12/100/12 | AO17: =MIN(Plan!E12,AM17+AN17) | AP17: =AM17+AN17-AO17 | AQ17: =MIN(AP17,MAX(0,$B17-((E$5<AO$5)*F17+(K$5<AO$5)*L17+(Q$5<AO$5)*R17+(W$5<AO$5)*X17+(AC$5<AO$5)*AD17+(AI$5<AO$5)*AJ17+(AU$5<AO$5)*AV17))) | AR17: =IF(AP17-AQ17<0.005,0,AP17-AQ17) | AS17: =AX16 | AT17: =AS17*Plan!D13/100/12 | AU17: =MIN(Plan!E13,AS17+AT17) | AV17: =AS17+AT17-AU17 | AW17: =MIN(AV17,MAX(0,$B17-((E$5<AU$5)*F17+(K$5<AU$5)*L17+(Q$5<AU$5)*R17+(W$5<AU$5)*X17+(AC$5<AU$5)*AD17+(AI$5<AU$5)*AJ17+(AO$5<AU$5)*AP17))) | AX17: =IF(AV17-AW17<0.005,0,AV17-AW17) | BC17: =H17+N17+T17+Z17+AF17+AL17+AR17+AX17
A18: 12 | B18: =MAX(0,$B$3-(E18+K18+Q18+W18+AC18+AI18+AO18+AU18)) | C18: =H17 | D18: =C18*Plan!D6/100/12 | E18: =MIN(Plan!E6,C18+D18) | F18: =C18+D18-E18 | G18: =MIN(F18,MAX(0,$B18-((K$5<E$5)*L18+(Q$5<E$5)*R18+(W$5<E$5)*X18+(AC$5<E$5)*AD18+(AI$5<E$5)*AJ18+(AO$5<E$5)*AP18+(AU$5<E$5)*AV18))) | H18: =IF(F18-G18<0.005,0,F18-G18) | I18: =N17 | J18: =I18*Plan!D7/100/12 | K18: =MIN(Plan!E7,I18+J18) | L18: =I18+J18-K18 | M18: =MIN(L18,MAX(0,$B18-((E$5<K$5)*F18+(Q$5<K$5)*R18+(W$5<K$5)*X18+(AC$5<K$5)*AD18+(AI$5<K$5)*AJ18+(AO$5<K$5)*AP18+(AU$5<K$5)*AV18))) | N18: =IF(L18-M18<0.005,0,L18-M18) | O18: =T17 | P18: =O18*Plan!D8/100/12 | Q18: =MIN(Plan!E8,O18+P18) | R18: =O18+P18-Q18 | S18: =MIN(R18,MAX(0,$B18-((E$5<Q$5)*F18+(K$5<Q$5)*L18+(W$5<Q$5)*X18+(AC$5<Q$5)*AD18+(AI$5<Q$5)*AJ18+(AO$5<Q$5)*AP18+(AU$5<Q$5)*AV18))) | T18: =IF(R18-S18<0.005,0,R18-S18) | U18: =Z17 | V18: =U18*Plan!D9/100/12 | W18: =MIN(Plan!E9,U18+V18) | X18: =U18+V18-W18 | Y18: =MIN(X18,MAX(0,$B18-((E$5<W$5)*F18+(K$5<W$5)*L18+(Q$5<W$5)*R18+(AC$5<W$5)*AD18+(AI$5<W$5)*AJ18+(AO$5<W$5)*AP18+(AU$5<W$5)*AV18))) | Z18: =IF(X18-Y18<0.005,0,X18-Y18) | AA18: =AF17 | AB18: =AA18*Plan!D10/100/12 | AC18: =MIN(Plan!E10,AA18+AB18) | AD18: =AA18+AB18-AC18 | AE18: =MIN(AD18,MAX(0,$B18-((E$5<AC$5)*F18+(K$5<AC$5)*L18+(Q$5<AC$5)*R18+(W$5<AC$5)*X18+(AI$5<AC$5)*AJ18+(AO$5<AC$5)*AP18+(AU$5<AC$5)*AV18))) | AF18: =IF(AD18-AE18<0.005,0,AD18-AE18) | AG18: =AL17 | AH18: =AG18*Plan!D11/100/12 | AI18: =MIN(Plan!E11,AG18+AH18) | AJ18: =AG18+AH18-AI18 | AK18: =MIN(AJ18,MAX(0,$B18-((E$5<AI$5)*F18+(K$5<AI$5)*L18+(Q$5<AI$5)*R18+(W$5<AI$5)*X18+(AC$5<AI$5)*AD18+(AO$5<AI$5)*AP18+(AU$5<AI$5)*AV18))) | AL18: =IF(AJ18-AK18<0.005,0,AJ18-AK18) | AM18: =AR17 | AN18: =AM18*Plan!D12/100/12 | AO18: =MIN(Plan!E12,AM18+AN18) | AP18: =AM18+AN18-AO18 | AQ18: =MIN(AP18,MAX(0,$B18-((E$5<AO$5)*F18+(K$5<AO$5)*L18+(Q$5<AO$5)*R18+(W$5<AO$5)*X18+(AC$5<AO$5)*AD18+(AI$5<AO$5)*AJ18+(AU$5<AO$5)*AV18))) | AR18: =IF(AP18-AQ18<0.005,0,AP18-AQ18) | AS18: =AX17 | AT18: =AS18*Plan!D13/100/12 | AU18: =MIN(Plan!E13,AS18+AT18) | AV18: =AS18+AT18-AU18 | AW18: =MIN(AV18,MAX(0,$B18-((E$5<AU$5)*F18+(K$5<AU$5)*L18+(Q$5<AU$5)*R18+(W$5<AU$5)*X18+(AC$5<AU$5)*AD18+(AI$5<AU$5)*AJ18+(AO$5<AU$5)*AP18))) | AX18: =IF(AV18-AW18<0.005,0,AV18-AW18) | BC18: =H18+N18+T18+Z18+AF18+AL18+AR18+AX18
A19: 13 | B19: =MAX(0,$B$3-(E19+K19+Q19+W19+AC19+AI19+AO19+AU19)) | C19: =H18 | D19: =C19*Plan!D6/100/12 | E19: =MIN(Plan!E6,C19+D19) | F19: =C19+D19-E19 | G19: =MIN(F19,MAX(0,$B19-((K$5<E$5)*L19+(Q$5<E$5)*R19+(W$5<E$5)*X19+(AC$5<E$5)*AD19+(AI$5<E$5)*AJ19+(AO$5<E$5)*AP19+(AU$5<E$5)*AV19))) | H19: =IF(F19-G19<0.005,0,F19-G19) | I19: =N18 | J19: =I19*Plan!D7/100/12 | K19: =MIN(Plan!E7,I19+J19) | L19: =I19+J19-K19 | M19: =MIN(L19,MAX(0,$B19-((E$5<K$5)*F19+(Q$5<K$5)*R19+(W$5<K$5)*X19+(AC$5<K$5)*AD19+(AI$5<K$5)*AJ19+(AO$5<K$5)*AP19+(AU$5<K$5)*AV19))) | N19: =IF(L19-M19<0.005,0,L19-M19) | O19: =T18 | P19: =O19*Plan!D8/100/12 | Q19: =MIN(Plan!E8,O19+P19) | R19: =O19+P19-Q19 | S19: =MIN(R19,MAX(0,$B19-((E$5<Q$5)*F19+(K$5<Q$5)*L19+(W$5<Q$5)*X19+(AC$5<Q$5)*AD19+(AI$5<Q$5)*AJ19+(AO$5<Q$5)*AP19+(AU$5<Q$5)*AV19))) | T19: =IF(R19-S19<0.005,0,R19-S19) | U19: =Z18 | V19: =U19*Plan!D9/100/12 | W19: =MIN(Plan!E9,U19+V19) | X19: =U19+V19-W19 | Y19: =MIN(X19,MAX(0,$B19-((E$5<W$5)*F19+(K$5<W$5)*L19+(Q$5<W$5)*R19+(AC$5<W$5)*AD19+(AI$5<W$5)*AJ19+(AO$5<W$5)*AP19+(AU$5<W$5)*AV19))) | Z19: =IF(X19-Y19<0.005,0,X19-Y19) | AA19: =AF18 | AB19: =AA19*Plan!D10/100/12 | AC19: =MIN(Plan!E10,AA19+AB19) | AD19: =AA19+AB19-AC19 | AE19: =MIN(AD19,MAX(0,$B19-((E$5<AC$5)*F19+(K$5<AC$5)*L19+(Q$5<AC$5)*R19+(W$5<AC$5)*X19+(AI$5<AC$5)*AJ19+(AO$5<AC$5)*AP19+(AU$5<AC$5)*AV19))) | AF19: =IF(AD19-AE19<0.005,0,AD19-AE19) | AG19: =AL18 | AH19: =AG19*Plan!D11/100/12 | AI19: =MIN(Plan!E11,AG19+AH19) | AJ19: =AG19+AH19-AI19 | AK19: =MIN(AJ19,MAX(0,$B19-((E$5<AI$5)*F19+(K$5<AI$5)*L19+(Q$5<AI$5)*R19+(W$5<AI$5)*X19+(AC$5<AI$5)*AD19+(AO$5<AI$5)*AP19+(AU$5<AI$5)*AV19))) | AL19: =IF(AJ19-AK19<0.005,0,AJ19-AK19) | AM19: =AR18 | AN19: =AM19*Plan!D12/100/12 | AO19: =MIN(Plan!E12,AM19+AN19) | AP19: =AM19+AN19-AO19 | AQ19: =MIN(AP19,MAX(0,$B19-((E$5<AO$5)*F19+(K$5<AO$5)*L19+(Q$5<AO$5)*R19+(W$5<AO$5)*X19+(AC$5<AO$5)*AD19+(AI$5<AO$5)*AJ19+(AU$5<AO$5)*AV19))) | AR19: =IF(AP19-AQ19<0.005,0,AP19-AQ19) | AS19: =AX18 | AT19: =AS19*Plan!D13/100/12 | AU19: =MIN(Plan!E13,AS19+AT19) | AV19: =AS19+AT19-AU19 | AW19: =MIN(AV19,MAX(0,$B19-((E$5<AU$5)*F19+(K$5<AU$5)*L19+(Q$5<AU$5)*R19+(W$5<AU$5)*X19+(AC$5<AU$5)*AD19+(AI$5<AU$5)*AJ19+(AO$5<AU$5)*AP19))) | AX19: =IF(AV19-AW19<0.005,0,AV19-AW19) | BC19: =H19+N19+T19+Z19+AF19+AL19+AR19+AX19
A20: 14 | B20: =MAX(0,$B$3-(E20+K20+Q20+W20+AC20+AI20+AO20+AU20)) | C20: =H19 | D20: =C20*Plan!D6/100/12 | E20: =MIN(Plan!E6,C20+D20) | F20: =C20+D20-E20 | G20: =MIN(F20,MAX(0,$B20-((K$5<E$5)*L20+(Q$5<E$5)*R20+(W$5<E$5)*X20+(AC$5<E$5)*AD20+(AI$5<E$5)*AJ20+(AO$5<E$5)*AP20+(AU$5<E$5)*AV20))) | H20: =IF(F20-G20<0.005,0,F20-G20) | I20: =N19 | J20: =I20*Plan!D7/100/12 | K20: =MIN(Plan!E7,I20+J20) | L20: =I20+J20-K20 | M20: =MIN(L20,MAX(0,$B20-((E$5<K$5)*F20+(Q$5<K$5)*R20+(W$5<K$5)*X20+(AC$5<K$5)*AD20+(AI$5<K$5)*AJ20+(AO$5<K$5)*AP20+(AU$5<K$5)*AV20))) | N20: =IF(L20-M20<0.005,0,L20-M20) | O20: =T19 | P20: =O20*Plan!D8/100/12 | Q20: =MIN(Plan!E8,O20+P20) | R20: =O20+P20-Q20 | S20: =MIN(R20,MAX(0,$B20-((E$5<Q$5)*F20+(K$5<Q$5)*L20+(W$5<Q$5)*X20+(AC$5<Q$5)*AD20+(AI$5<Q$5)*AJ20+(AO$5<Q$5)*AP20+(AU$5<Q$5)*AV20))) | T20: =IF(R20-S20<0.005,0,R20-S20) | U20: =Z19 | V20: =U20*Plan!D9/100/12 | W20: =MIN(Plan!E9,U20+V20) | X20: =U20+V20-W20 | Y20: =MIN(X20,MAX(0,$B20-((E$5<W$5)*F20+(K$5<W$5)*L20+(Q$5<W$5)*R20+(AC$5<W$5)*AD20+(AI$5<W$5)*AJ20+(AO$5<W$5)*AP20+(AU$5<W$5)*AV20))) | Z20: =IF(X20-Y20<0.005,0,X20-Y20) | AA20: =AF19 | AB20: =AA20*Plan!D10/100/12 | AC20: =MIN(Plan!E10,AA20+AB20) | AD20: =AA20+AB20-AC20 | AE20: =MIN(AD20,MAX(0,$B20-((E$5<AC$5)*F20+(K$5<AC$5)*L20+(Q$5<AC$5)*R20+(W$5<AC$5)*X20+(AI$5<AC$5)*AJ20+(AO$5<AC$5)*AP20+(AU$5<AC$5)*AV20))) | AF20: =IF(AD20-AE20<0.005,0,AD20-AE20) | AG20: =AL19 | AH20: =AG20*Plan!D11/100/12 | AI20: =MIN(Plan!E11,AG20+AH20) | AJ20: =AG20+AH20-AI20 | AK20: =MIN(AJ20,MAX(0,$B20-((E$5<AI$5)*F20+(K$5<AI$5)*L20+(Q$5<AI$5)*R20+(W$5<AI$5)*X20+(AC$5<AI$5)*AD20+(AO$5<AI$5)*AP20+(AU$5<AI$5)*AV20))) | AL20: =IF(AJ20-AK20<0.005,0,AJ20-AK20) | AM20: =AR19 | AN20: =AM20*Plan!D12/100/12 | AO20: =MIN(Plan!E12,AM20+AN20) | AP20: =AM20+AN20-AO20 | AQ20: =MIN(AP20,MAX(0,$B20-((E$5<AO$5)*F20+(K$5<AO$5)*L20+(Q$5<AO$5)*R20+(W$5<AO$5)*X20+(AC$5<AO$5)*AD20+(AI$5<AO$5)*AJ20+(AU$5<AO$5)*AV20))) | AR20: =IF(AP20-AQ20<0.005,0,AP20-AQ20) | AS20: =AX19 | AT20: =AS20*Plan!D13/100/12 | AU20: =MIN(Plan!E13,AS20+AT20) | AV20: =AS20+AT20-AU20 | AW20: =MIN(AV20,MAX(0,$B20-((E$5<AU$5)*F20+(K$5<AU$5)*L20+(Q$5<AU$5)*R20+(W$5<AU$5)*X20+(AC$5<AU$5)*AD20+(AI$5<AU$5)*AJ20+(AO$5<AU$5)*AP20))) | AX20: =IF(AV20-AW20<0.005,0,AV20-AW20) | BC20: =H20+N20+T20+Z20+AF20+AL20+AR20+AX20
A21: 15 | B21: =MAX(0,$B$3-(E21+K21+Q21+W21+AC21+AI21+AO21+AU21)) | C21: =H20 | D21: =C21*Plan!D6/100/12 | E21: =MIN(Plan!E6,C21+D21) | F21: =C21+D21-E21 | G21: =MIN(F21,MAX(0,$B21-((K$5<E$5)*L21+(Q$5<E$5)*R21+(W$5<E$5)*X21+(AC$5<E$5)*AD21+(AI$5<E$5)*AJ21+(AO$5<E$5)*AP21+(AU$5<E$5)*AV21))) | H21: =IF(F21-G21<0.005,0,F21-G21) | I21: =N20 | J21: =I21*Plan!D7/100/12 | K21: =MIN(Plan!E7,I21+J21) | L21: =I21+J21-K21 | M21: =MIN(L21,MAX(0,$B21-((E$5<K$5)*F21+(Q$5<K$5)*R21+(W$5<K$5)*X21+(AC$5<K$5)*AD21+(AI$5<K$5)*AJ21+(AO$5<K$5)*AP21+(AU$5<K$5)*AV21))) | N21: =IF(L21-M21<0.005,0,L21-M21) | O21: =T20 | P21: =O21*Plan!D8/100/12 | Q21: =MIN(Plan!E8,O21+P21) | R21: =O21+P21-Q21 | S21: =MIN(R21,MAX(0,$B21-((E$5<Q$5)*F21+(K$5<Q$5)*L21+(W$5<Q$5)*X21+(AC$5<Q$5)*AD21+(AI$5<Q$5)*AJ21+(AO$5<Q$5)*AP21+(AU$5<Q$5)*AV21))) | T21: =IF(R21-S21<0.005,0,R21-S21) | U21: =Z20 | V21: =U21*Plan!D9/100/12 | W21: =MIN(Plan!E9,U21+V21) | X21: =U21+V21-W21 | Y21: =MIN(X21,MAX(0,$B21-((E$5<W$5)*F21+(K$5<W$5)*L21+(Q$5<W$5)*R21+(AC$5<W$5)*AD21+(AI$5<W$5)*AJ21+(AO$5<W$5)*AP21+(AU$5<W$5)*AV21))) | Z21: =IF(X21-Y21<0.005,0,X21-Y21) | AA21: =AF20 | AB21: =AA21*Plan!D10/100/12 | AC21: =MIN(Plan!E10,AA21+AB21) | AD21: =AA21+AB21-AC21 | AE21: =MIN(AD21,MAX(0,$B21-((E$5<AC$5)*F21+(K$5<AC$5)*L21+(Q$5<AC$5)*R21+(W$5<AC$5)*X21+(AI$5<AC$5)*AJ21+(AO$5<AC$5)*AP21+(AU$5<AC$5)*AV21))) | AF21: =IF(AD21-AE21<0.005,0,AD21-AE21) | AG21: =AL20 | AH21: =AG21*Plan!D11/100/12 | AI21: =MIN(Plan!E11,AG21+AH21) | AJ21: =AG21+AH21-AI21 | AK21: =MIN(AJ21,MAX(0,$B21-((E$5<AI$5)*F21+(K$5<AI$5)*L21+(Q$5<AI$5)*R21+(W$5<AI$5)*X21+(AC$5<AI$5)*AD21+(AO$5<AI$5)*AP21+(AU$5<AI$5)*AV21))) | AL21: =IF(AJ21-AK21<0.005,0,AJ21-AK21) | AM21: =AR20 | AN21: =AM21*Plan!D12/100/12 | AO21: =MIN(Plan!E12,AM21+AN21) | AP21: =AM21+AN21-AO21 | AQ21: =MIN(AP21,MAX(0,$B21-((E$5<AO$5)*F21+(K$5<AO$5)*L21+(Q$5<AO$5)*R21+(W$5<AO$5)*X21+(AC$5<AO$5)*AD21+(AI$5<AO$5)*AJ21+(AU$5<AO$5)*AV21))) | AR21: =IF(AP21-AQ21<0.005,0,AP21-AQ21) | AS21: =AX20 | AT21: =AS21*Plan!D13/100/12 | AU21: =MIN(Plan!E13,AS21+AT21) | AV21: =AS21+AT21-AU21 | AW21: =MIN(AV21,MAX(0,$B21-((E$5<AU$5)*F21+(K$5<AU$5)*L21+(Q$5<AU$5)*R21+(W$5<AU$5)*X21+(AC$5<AU$5)*AD21+(AI$5<AU$5)*AJ21+(AO$5<AU$5)*AP21))) | AX21: =IF(AV21-AW21<0.005,0,AV21-AW21) | BC21: =H21+N21+T21+Z21+AF21+AL21+AR21+AX21
A22: 16 | B22: =MAX(0,$B$3-(E22+K22+Q22+W22+AC22+AI22+AO22+AU22)) | C22: =H21 | D22: =C22*Plan!D6/100/12 | E22: =MIN(Plan!E6,C22+D22) | F22: =C22+D22-E22 | G22: =MIN(F22,MAX(0,$B22-((K$5<E$5)*L22+(Q$5<E$5)*R22+(W$5<E$5)*X22+(AC$5<E$5)*AD22+(AI$5<E$5)*AJ22+(AO$5<E$5)*AP22+(AU$5<E$5)*AV22))) | H22: =IF(F22-G22<0.005,0,F22-G22) | I22: =N21 | J22: =I22*Plan!D7/100/12 | K22: =MIN(Plan!E7,I22+J22) | L22: =I22+J22-K22 | M22: =MIN(L22,MAX(0,$B22-((E$5<K$5)*F22+(Q$5<K$5)*R22+(W$5<K$5)*X22+(AC$5<K$5)*AD22+(AI$5<K$5)*AJ22+(AO$5<K$5)*AP22+(AU$5<K$5)*AV22))) | N22: =IF(L22-M22<0.005,0,L22-M22) | O22: =T21 | P22: =O22*Plan!D8/100/12 | Q22: =MIN(Plan!E8,O22+P22) | R22: =O22+P22-Q22 | S22: =MIN(R22,MAX(0,$B22-((E$5<Q$5)*F22+(K$5<Q$5)*L22+(W$5<Q$5)*X22+(AC$5<Q$5)*AD22+(AI$5<Q$5)*AJ22+(AO$5<Q$5)*AP22+(AU$5<Q$5)*AV22))) | T22: =IF(R22-S22<0.005,0,R22-S22) | U22: =Z21 | V22: =U22*Plan!D9/100/12 | W22: =MIN(Plan!E9,U22+V22) | X22: =U22+V22-W22 | Y22: =MIN(X22,MAX(0,$B22-((E$5<W$5)*F22+(K$5<W$5)*L22+(Q$5<W$5)*R22+(AC$5<W$5)*AD22+(AI$5<W$5)*AJ22+(AO$5<W$5)*AP22+(AU$5<W$5)*AV22))) | Z22: =IF(X22-Y22<0.005,0,X22-Y22) | AA22: =AF21 | AB22: =AA22*Plan!D10/100/12 | AC22: =MIN(Plan!E10,AA22+AB22) | AD22: =AA22+AB22-AC22 | AE22: =MIN(AD22,MAX(0,$B22-((E$5<AC$5)*F22+(K$5<AC$5)*L22+(Q$5<AC$5)*R22+(W$5<AC$5)*X22+(AI$5<AC$5)*AJ22+(AO$5<AC$5)*AP22+(AU$5<AC$5)*AV22))) | AF22: =IF(AD22-AE22<0.005,0,AD22-AE22) | AG22: =AL21 | AH22: =AG22*Plan!D11/100/12 | AI22: =MIN(Plan!E11,AG22+AH22) | AJ22: =AG22+AH22-AI22 | AK22: =MIN(AJ22,MAX(0,$B22-((E$5<AI$5)*F22+(K$5<AI$5)*L22+(Q$5<AI$5)*R22+(W$5<AI$5)*X22+(AC$5<AI$5)*AD22+(AO$5<AI$5)*AP22+(AU$5<AI$5)*AV22))) | AL22: =IF(AJ22-AK22<0.005,0,AJ22-AK22) | AM22: =AR21 | AN22: =AM22*Plan!D12/100/12 | AO22: =MIN(Plan!E12,AM22+AN22) | AP22: =AM22+AN22-AO22 | AQ22: =MIN(AP22,MAX(0,$B22-((E$5<AO$5)*F22+(K$5<AO$5)*L22+(Q$5<AO$5)*R22+(W$5<AO$5)*X22+(AC$5<AO$5)*AD22+(AI$5<AO$5)*AJ22+(AU$5<AO$5)*AV22))) | AR22: =IF(AP22-AQ22<0.005,0,AP22-AQ22) | AS22: =AX21 | AT22: =AS22*Plan!D13/100/12 | AU22: =MIN(Plan!E13,AS22+AT22) | AV22: =AS22+AT22-AU22 | AW22: =MIN(AV22,MAX(0,$B22-((E$5<AU$5)*F22+(K$5<AU$5)*L22+(Q$5<AU$5)*R22+(W$5<AU$5)*X22+(AC$5<AU$5)*AD22+(AI$5<AU$5)*AJ22+(AO$5<AU$5)*AP22))) | AX22: =IF(AV22-AW22<0.005,0,AV22-AW22) | BC22: =H22+N22+T22+Z22+AF22+AL22+AR22+AX22
A23: 17 | B23: =MAX(0,$B$3-(E23+K23+Q23+W23+AC23+AI23+AO23+AU23)) | C23: =H22 | D23: =C23*Plan!D6/100/12 | E23: =MIN(Plan!E6,C23+D23) | F23: =C23+D23-E23 | G23: =MIN(F23,MAX(0,$B23-((K$5<E$5)*L23+(Q$5<E$5)*R23+(W$5<E$5)*X23+(AC$5<E$5)*AD23+(AI$5<E$5)*AJ23+(AO$5<E$5)*AP23+(AU$5<E$5)*AV23))) | H23: =IF(F23-G23<0.005,0,F23-G23) | I23: =N22 | J23: =I23*Plan!D7/100/12 | K23: =MIN(Plan!E7,I23+J23) | L23: =I23+J23-K23 | M23: =MIN(L23,MAX(0,$B23-((E$5<K$5)*F23+(Q$5<K$5)*R23+(W$5<K$5)*X23+(AC$5<K$5)*AD23+(AI$5<K$5)*AJ23+(AO$5<K$5)*AP23+(AU$5<K$5)*AV23))) | N23: =IF(L23-M23<0.005,0,L23-M23) | O23: =T22 | P23: =O23*Plan!D8/100/12 | Q23: =MIN(Plan!E8,O23+P23) | R23: =O23+P23-Q23 | S23: =MIN(R23,MAX(0,$B23-((E$5<Q$5)*F23+(K$5<Q$5)*L23+(W$5<Q$5)*X23+(AC$5<Q$5)*AD23+(AI$5<Q$5)*AJ23+(AO$5<Q$5)*AP23+(AU$5<Q$5)*AV23))) | T23: =IF(R23-S23<0.005,0,R23-S23) | U23: =Z22 | V23: =U23*Plan!D9/100/12 | W23: =MIN(Plan!E9,U23+V23) | X23: =U23+V23-W23 | Y23: =MIN(X23,MAX(0,$B23-((E$5<W$5)*F23+(K$5<W$5)*L23+(Q$5<W$5)*R23+(AC$5<W$5)*AD23+(AI$5<W$5)*AJ23+(AO$5<W$5)*AP23+(AU$5<W$5)*AV23))) | Z23: =IF(X23-Y23<0.005,0,X23-Y23) | AA23: =AF22 | AB23: =AA23*Plan!D10/100/12 | AC23: =MIN(Plan!E10,AA23+AB23) | AD23: =AA23+AB23-AC23 | AE23: =MIN(AD23,MAX(0,$B23-((E$5<AC$5)*F23+(K$5<AC$5)*L23+(Q$5<AC$5)*R23+(W$5<AC$5)*X23+(AI$5<AC$5)*AJ23+(AO$5<AC$5)*AP23+(AU$5<AC$5)*AV23))) | AF23: =IF(AD23-AE23<0.005,0,AD23-AE23) | AG23: =AL22 | AH23: =AG23*Plan!D11/100/12 | AI23: =MIN(Plan!E11,AG23+AH23) | AJ23: =AG23+AH23-AI23 | AK23: =MIN(AJ23,MAX(0,$B23-((E$5<AI$5)*F23+(K$5<AI$5)*L23+(Q$5<AI$5)*R23+(W$5<AI$5)*X23+(AC$5<AI$5)*AD23+(AO$5<AI$5)*AP23+(AU$5<AI$5)*AV23))) | AL23: =IF(AJ23-AK23<0.005,0,AJ23-AK23) | AM23: =AR22 | AN23: =AM23*Plan!D12/100/12 | AO23: =MIN(Plan!E12,AM23+AN23) | AP23: =AM23+AN23-AO23 | AQ23: =MIN(AP23,MAX(0,$B23-((E$5<AO$5)*F23+(K$5<AO$5)*L23+(Q$5<AO$5)*R23+(W$5<AO$5)*X23+(AC$5<AO$5)*AD23+(AI$5<AO$5)*AJ23+(AU$5<AO$5)*AV23))) | AR23: =IF(AP23-AQ23<0.005,0,AP23-AQ23) | AS23: =AX22 | AT23: =AS23*Plan!D13/100/12 | AU23: =MIN(Plan!E13,AS23+AT23) | AV23: =AS23+AT23-AU23 | AW23: =MIN(AV23,MAX(0,$B23-((E$5<AU$5)*F23+(K$5<AU$5)*L23+(Q$5<AU$5)*R23+(W$5<AU$5)*X23+(AC$5<AU$5)*AD23+(AI$5<AU$5)*AJ23+(AO$5<AU$5)*AP23))) | AX23: =IF(AV23-AW23<0.005,0,AV23-AW23) | BC23: =H23+N23+T23+Z23+AF23+AL23+AR23+AX23
A24: 18 | B24: =MAX(0,$B$3-(E24+K24+Q24+W24+AC24+AI24+AO24+AU24)) | C24: =H23 | D24: =C24*Plan!D6/100/12 | E24: =MIN(Plan!E6,C24+D24) | F24: =C24+D24-E24 | G24: =MIN(F24,MAX(0,$B24-((K$5<E$5)*L24+(Q$5<E$5)*R24+(W$5<E$5)*X24+(AC$5<E$5)*AD24+(AI$5<E$5)*AJ24+(AO$5<E$5)*AP24+(AU$5<E$5)*AV24))) | H24: =IF(F24-G24<0.005,0,F24-G24) | I24: =N23 | J24: =I24*Plan!D7/100/12 | K24: =MIN(Plan!E7,I24+J24) | L24: =I24+J24-K24 | M24: =MIN(L24,MAX(0,$B24-((E$5<K$5)*F24+(Q$5<K$5)*R24+(W$5<K$5)*X24+(AC$5<K$5)*AD24+(AI$5<K$5)*AJ24+(AO$5<K$5)*AP24+(AU$5<K$5)*AV24))) | N24: =IF(L24-M24<0.005,0,L24-M24) | O24: =T23 | P24: =O24*Plan!D8/100/12 | Q24: =MIN(Plan!E8,O24+P24) | R24: =O24+P24-Q24 | S24: =MIN(R24,MAX(0,$B24-((E$5<Q$5)*F24+(K$5<Q$5)*L24+(W$5<Q$5)*X24+(AC$5<Q$5)*AD24+(AI$5<Q$5)*AJ24+(AO$5<Q$5)*AP24+(AU$5<Q$5)*AV24))) | T24: =IF(R24-S24<0.005,0,R24-S24) | U24: =Z23 | V24: =U24*Plan!D9/100/12 | W24: =MIN(Plan!E9,U24+V24) | X24: =U24+V24-W24 | Y24: =MIN(X24,MAX(0,$B24-((E$5<W$5)*F24+(K$5<W$5)*L24+(Q$5<W$5)*R24+(AC$5<W$5)*AD24+(AI$5<W$5)*AJ24+(AO$5<W$5)*AP24+(AU$5<W$5)*AV24))) | Z24: =IF(X24-Y24<0.005,0,X24-Y24) | AA24: =AF23 | AB24: =AA24*Plan!D10/100/12 | AC24: =MIN(Plan!E10,AA24+AB24) | AD24: =AA24+AB24-AC24 | AE24: =MIN(AD24,MAX(0,$B24-((E$5<AC$5)*F24+(K$5<AC$5)*L24+(Q$5<AC$5)*R24+(W$5<AC$5)*X24+(AI$5<AC$5)*AJ24+(AO$5<AC$5)*AP24+(AU$5<AC$5)*AV24))) | AF24: =IF(AD24-AE24<0.005,0,AD24-AE24) | AG24: =AL23 | AH24: =AG24*Plan!D11/100/12 | AI24: =MIN(Plan!E11,AG24+AH24) | AJ24: =AG24+AH24-AI24 | AK24: =MIN(AJ24,MAX(0,$B24-((E$5<AI$5)*F24+(K$5<AI$5)*L24+(Q$5<AI$5)*R24+(W$5<AI$5)*X24+(AC$5<AI$5)*AD24+(AO$5<AI$5)*AP24+(AU$5<AI$5)*AV24))) | AL24: =IF(AJ24-AK24<0.005,0,AJ24-AK24) | AM24: =AR23 | AN24: =AM24*Plan!D12/100/12 | AO24: =MIN(Plan!E12,AM24+AN24) | AP24: =AM24+AN24-AO24 | AQ24: =MIN(AP24,MAX(0,$B24-((E$5<AO$5)*F24+(K$5<AO$5)*L24+(Q$5<AO$5)*R24+(W$5<AO$5)*X24+(AC$5<AO$5)*AD24+(AI$5<AO$5)*AJ24+(AU$5<AO$5)*AV24))) | AR24: =IF(AP24-AQ24<0.005,0,AP24-AQ24) | AS24: =AX23 | AT24: =AS24*Plan!D13/100/12 | AU24: =MIN(Plan!E13,AS24+AT24) | AV24: =AS24+AT24-AU24 | AW24: =MIN(AV24,MAX(0,$B24-((E$5<AU$5)*F24+(K$5<AU$5)*L24+(Q$5<AU$5)*R24+(W$5<AU$5)*X24+(AC$5<AU$5)*AD24+(AI$5<AU$5)*AJ24+(AO$5<AU$5)*AP24))) | AX24: =IF(AV24-AW24<0.005,0,AV24-AW24) | BC24: =H24+N24+T24+Z24+AF24+AL24+AR24+AX24
A25: 19 | B25: =MAX(0,$B$3-(E25+K25+Q25+W25+AC25+AI25+AO25+AU25)) | C25: =H24 | D25: =C25*Plan!D6/100/12 | E25: =MIN(Plan!E6,C25+D25) | F25: =C25+D25-E25 | G25: =MIN(F25,MAX(0,$B25-((K$5<E$5)*L25+(Q$5<E$5)*R25+(W$5<E$5)*X25+(AC$5<E$5)*AD25+(AI$5<E$5)*AJ25+(AO$5<E$5)*AP25+(AU$5<E$5)*AV25))) | H25: =IF(F25-G25<0.005,0,F25-G25) | I25: =N24 | J25: =I25*Plan!D7/100/12 | K25: =MIN(Plan!E7,I25+J25) | L25: =I25+J25-K25 | M25: =MIN(L25,MAX(0,$B25-((E$5<K$5)*F25+(Q$5<K$5)*R25+(W$5<K$5)*X25+(AC$5<K$5)*AD25+(AI$5<K$5)*AJ25+(AO$5<K$5)*AP25+(AU$5<K$5)*AV25))) | N25: =IF(L25-M25<0.005,0,L25-M25) | O25: =T24 | P25: =O25*Plan!D8/100/12 | Q25: =MIN(Plan!E8,O25+P25) | R25: =O25+P25-Q25 | S25: =MIN(R25,MAX(0,$B25-((E$5<Q$5)*F25+(K$5<Q$5)*L25+(W$5<Q$5)*X25+(AC$5<Q$5)*AD25+(AI$5<Q$5)*AJ25+(AO$5<Q$5)*AP25+(AU$5<Q$5)*AV25))) | T25: =IF(R25-S25<0.005,0,R25-S25) | U25: =Z24 | V25: =U25*Plan!D9/100/12 | W25: =MIN(Plan!E9,U25+V25) | X25: =U25+V25-W25 | Y25: =MIN(X25,MAX(0,$B25-((E$5<W$5)*F25+(K$5<W$5)*L25+(Q$5<W$5)*R25+(AC$5<W$5)*AD25+(AI$5<W$5)*AJ25+(AO$5<W$5)*AP25+(AU$5<W$5)*AV25))) | Z25: =IF(X25-Y25<0.005,0,X25-Y25) | AA25: =AF24 | AB25: =AA25*Plan!D10/100/12 | AC25: =MIN(Plan!E10,AA25+AB25) | AD25: =AA25+AB25-AC25 | AE25: =MIN(AD25,MAX(0,$B25-((E$5<AC$5)*F25+(K$5<AC$5)*L25+(Q$5<AC$5)*R25+(W$5<AC$5)*X25+(AI$5<AC$5)*AJ25+(AO$5<AC$5)*AP25+(AU$5<AC$5)*AV25))) | AF25: =IF(AD25-AE25<0.005,0,AD25-AE25) | AG25: =AL24 | AH25: =AG25*Plan!D11/100/12 | AI25: =MIN(Plan!E11,AG25+AH25) | AJ25: =AG25+AH25-AI25 | AK25: =MIN(AJ25,MAX(0,$B25-((E$5<AI$5)*F25+(K$5<AI$5)*L25+(Q$5<AI$5)*R25+(W$5<AI$5)*X25+(AC$5<AI$5)*AD25+(AO$5<AI$5)*AP25+(AU$5<AI$5)*AV25))) | AL25: =IF(AJ25-AK25<0.005,0,AJ25-AK25) | AM25: =AR24 | AN25: =AM25*Plan!D12/100/12 | AO25: =MIN(Plan!E12,AM25+AN25) | AP25: =AM25+AN25-AO25 | AQ25: =MIN(AP25,MAX(0,$B25-((E$5<AO$5)*F25+(K$5<AO$5)*L25+(Q$5<AO$5)*R25+(W$5<AO$5)*X25+(AC$5<AO$5)*AD25+(AI$5<AO$5)*AJ25+(AU$5<AO$5)*AV25))) | AR25: =IF(AP25-AQ25<0.005,0,AP25-AQ25) | AS25: =AX24 | AT25: =AS25*Plan!D13/100/12 | AU25: =MIN(Plan!E13,AS25+AT25) | AV25: =AS25+AT25-AU25 | AW25: =MIN(AV25,MAX(0,$B25-((E$5<AU$5)*F25+(K$5<AU$5)*L25+(Q$5<AU$5)*R25+(W$5<AU$5)*X25+(AC$5<AU$5)*AD25+(AI$5<AU$5)*AJ25+(AO$5<AU$5)*AP25))) | AX25: =IF(AV25-AW25<0.005,0,AV25-AW25) | BC25: =H25+N25+T25+Z25+AF25+AL25+AR25+AX25
A26: 20 | B26: =MAX(0,$B$3-(E26+K26+Q26+W26+AC26+AI26+AO26+AU26)) | C26: =H25 | D26: =C26*Plan!D6/100/12 | E26: =MIN(Plan!E6,C26+D26) | F26: =C26+D26-E26 | G26: =MIN(F26,MAX(0,$B26-((K$5<E$5)*L26+(Q$5<E$5)*R26+(W$5<E$5)*X26+(AC$5<E$5)*AD26+(AI$5<E$5)*AJ26+(AO$5<E$5)*AP26+(AU$5<E$5)*AV26))) | H26: =IF(F26-G26<0.005,0,F26-G26) | I26: =N25 | J26: =I26*Plan!D7/100/12 | K26: =MIN(Plan!E7,I26+J26) | L26: =I26+J26-K26 | M26: =MIN(L26,MAX(0,$B26-((E$5<K$5)*F26+(Q$5<K$5)*R26+(W$5<K$5)*X26+(AC$5<K$5)*AD26+(AI$5<K$5)*AJ26+(AO$5<K$5)*AP26+(AU$5<K$5)*AV26))) | N26: =IF(L26-M26<0.005,0,L26-M26) | O26: =T25 | P26: =O26*Plan!D8/100/12 | Q26: =MIN(Plan!E8,O26+P26) | R26: =O26+P26-Q26 | S26: =MIN(R26,MAX(0,$B26-((E$5<Q$5)*F26+(K$5<Q$5)*L26+(W$5<Q$5)*X26+(AC$5<Q$5)*AD26+(AI$5<Q$5)*AJ26+(AO$5<Q$5)*AP26+(AU$5<Q$5)*AV26))) | T26: =IF(R26-S26<0.005,0,R26-S26) | U26: =Z25 | V26: =U26*Plan!D9/100/12 | W26: =MIN(Plan!E9,U26+V26) | X26: =U26+V26-W26 | Y26: =MIN(X26,MAX(0,$B26-((E$5<W$5)*F26+(K$5<W$5)*L26+(Q$5<W$5)*R26+(AC$5<W$5)*AD26+(AI$5<W$5)*AJ26+(AO$5<W$5)*AP26+(AU$5<W$5)*AV26))) | Z26: =IF(X26-Y26<0.005,0,X26-Y26) | AA26: =AF25 | AB26: =AA26*Plan!D10/100/12 | AC26: =MIN(Plan!E10,AA26+AB26) | AD26: =AA26+AB26-AC26 | AE26: =MIN(AD26,MAX(0,$B26-((E$5<AC$5)*F26+(K$5<AC$5)*L26+(Q$5<AC$5)*R26+(W$5<AC$5)*X26+(AI$5<AC$5)*AJ26+(AO$5<AC$5)*AP26+(AU$5<AC$5)*AV26))) | AF26: =IF(AD26-AE26<0.005,0,AD26-AE26) | AG26: =AL25 | AH26: =AG26*Plan!D11/100/12 | AI26: =MIN(Plan!E11,AG26+AH26) | AJ26: =AG26+AH26-AI26 | AK26: =MIN(AJ26,MAX(0,$B26-((E$5<AI$5)*F26+(K$5<AI$5)*L26+(Q$5<AI$5)*R26+(W$5<AI$5)*X26+(AC$5<AI$5)*AD26+(AO$5<AI$5)*AP26+(AU$5<AI$5)*AV26))) | AL26: =IF(AJ26-AK26<0.005,0,AJ26-AK26) | AM26: =AR25 | AN26: =AM26*Plan!D12/100/12 | AO26: =MIN(Plan!E12,AM26+AN26) | AP26: =AM26+AN26-AO26 | AQ26: =MIN(AP26,MAX(0,$B26-((E$5<AO$5)*F26+(K$5<AO$5)*L26+(Q$5<AO$5)*R26+(W$5<AO$5)*X26+(AC$5<AO$5)*AD26+(AI$5<AO$5)*AJ26+(AU$5<AO$5)*AV26))) | AR26: =IF(AP26-AQ26<0.005,0,AP26-AQ26) | AS26: =AX25 | AT26: =AS26*Plan!D13/100/12 | AU26: =MIN(Plan!E13,AS26+AT26) | AV26: =AS26+AT26-AU26 | AW26: =MIN(AV26,MAX(0,$B26-((E$5<AU$5)*F26+(K$5<AU$5)*L26+(Q$5<AU$5)*R26+(W$5<AU$5)*X26+(AC$5<AU$5)*AD26+(AI$5<AU$5)*AJ26+(AO$5<AU$5)*AP26))) | AX26: =IF(AV26-AW26<0.005,0,AV26-AW26) | BC26: =H26+N26+T26+Z26+AF26+AL26+AR26+AX26
A27: 21 | B27: =MAX(0,$B$3-(E27+K27+Q27+W27+AC27+AI27+AO27+AU27)) | C27: =H26 | D27: =C27*Plan!D6/100/12 | E27: =MIN(Plan!E6,C27+D27) | F27: =C27+D27-E27 | G27: =MIN(F27,MAX(0,$B27-((K$5<E$5)*L27+(Q$5<E$5)*R27+(W$5<E$5)*X27+(AC$5<E$5)*AD27+(AI$5<E$5)*AJ27+(AO$5<E$5)*AP27+(AU$5<E$5)*AV27))) | H27: =IF(F27-G27<0.005,0,F27-G27) | I27: =N26 | J27: =I27*Plan!D7/100/12 | K27: =MIN(Plan!E7,I27+J27) | L27: =I27+J27-K27 | M27: =MIN(L27,MAX(0,$B27-((E$5<K$5)*F27+(Q$5<K$5)*R27+(W$5<K$5)*X27+(AC$5<K$5)*AD27+(AI$5<K$5)*AJ27+(AO$5<K$5)*AP27+(AU$5<K$5)*AV27))) | N27: =IF(L27-M27<0.005,0,L27-M27) | O27: =T26 | P27: =O27*Plan!D8/100/12 | Q27: =MIN(Plan!E8,O27+P27) | R27: =O27+P27-Q27 | S27: =MIN(R27,MAX(0,$B27-((E$5<Q$5)*F27+(K$5<Q$5)*L27+(W$5<Q$5)*X27+(AC$5<Q$5)*AD27+(AI$5<Q$5)*AJ27+(AO$5<Q$5)*AP27+(AU$5<Q$5)*AV27))) | T27: =IF(R27-S27<0.005,0,R27-S27) | U27: =Z26 | V27: =U27*Plan!D9/100/12 | W27: =MIN(Plan!E9,U27+V27) | X27: =U27+V27-W27 | Y27: =MIN(X27,MAX(0,$B27-((E$5<W$5)*F27+(K$5<W$5)*L27+(Q$5<W$5)*R27+(AC$5<W$5)*AD27+(AI$5<W$5)*AJ27+(AO$5<W$5)*AP27+(AU$5<W$5)*AV27))) | Z27: =IF(X27-Y27<0.005,0,X27-Y27) | AA27: =AF26 | AB27: =AA27*Plan!D10/100/12 | AC27: =MIN(Plan!E10,AA27+AB27) | AD27: =AA27+AB27-AC27 | AE27: =MIN(AD27,MAX(0,$B27-((E$5<AC$5)*F27+(K$5<AC$5)*L27+(Q$5<AC$5)*R27+(W$5<AC$5)*X27+(AI$5<AC$5)*AJ27+(AO$5<AC$5)*AP27+(AU$5<AC$5)*AV27))) | AF27: =IF(AD27-AE27<0.005,0,AD27-AE27) | AG27: =AL26 | AH27: =AG27*Plan!D11/100/12 | AI27: =MIN(Plan!E11,AG27+AH27) | AJ27: =AG27+AH27-AI27 | AK27: =MIN(AJ27,MAX(0,$B27-((E$5<AI$5)*F27+(K$5<AI$5)*L27+(Q$5<AI$5)*R27+(W$5<AI$5)*X27+(AC$5<AI$5)*AD27+(AO$5<AI$5)*AP27+(AU$5<AI$5)*AV27))) | AL27: =IF(AJ27-AK27<0.005,0,AJ27-AK27) | AM27: =AR26 | AN27: =AM27*Plan!D12/100/12 | AO27: =MIN(Plan!E12,AM27+AN27) | AP27: =AM27+AN27-AO27 | AQ27: =MIN(AP27,MAX(0,$B27-((E$5<AO$5)*F27+(K$5<AO$5)*L27+(Q$5<AO$5)*R27+(W$5<AO$5)*X27+(AC$5<AO$5)*AD27+(AI$5<AO$5)*AJ27+(AU$5<AO$5)*AV27))) | AR27: =IF(AP27-AQ27<0.005,0,AP27-AQ27) | AS27: =AX26 | AT27: =AS27*Plan!D13/100/12 | AU27: =MIN(Plan!E13,AS27+AT27) | AV27: =AS27+AT27-AU27 | AW27: =MIN(AV27,MAX(0,$B27-((E$5<AU$5)*F27+(K$5<AU$5)*L27+(Q$5<AU$5)*R27+(W$5<AU$5)*X27+(AC$5<AU$5)*AD27+(AI$5<AU$5)*AJ27+(AO$5<AU$5)*AP27))) | AX27: =IF(AV27-AW27<0.005,0,AV27-AW27) | BC27: =H27+N27+T27+Z27+AF27+AL27+AR27+AX27
A28: 22 | B28: =MAX(0,$B$3-(E28+K28+Q28+W28+AC28+AI28+AO28+AU28)) | C28: =H27 | D28: =C28*Plan!D6/100/12 | E28: =MIN(Plan!E6,C28+D28) | F28: =C28+D28-E28 | G28: =MIN(F28,MAX(0,$B28-((K$5<E$5)*L28+(Q$5<E$5)*R28+(W$5<E$5)*X28+(AC$5<E$5)*AD28+(AI$5<E$5)*AJ28+(AO$5<E$5)*AP28+(AU$5<E$5)*AV28))) | H28: =IF(F28-G28<0.005,0,F28-G28) | I28: =N27 | J28: =I28*Plan!D7/100/12 | K28: =MIN(Plan!E7,I28+J28) | L28: =I28+J28-K28 | M28: =MIN(L28,MAX(0,$B28-((E$5<K$5)*F28+(Q$5<K$5)*R28+(W$5<K$5)*X28+(AC$5<K$5)*AD28+(AI$5<K$5)*AJ28+(AO$5<K$5)*AP28+(AU$5<K$5)*AV28))) | N28: =IF(L28-M28<0.005,0,L28-M28) | O28: =T27 | P28: =O28*Plan!D8/100/12 | Q28: =MIN(Plan!E8,O28+P28) | R28: =O28+P28-Q28 | S28: =MIN(R28,MAX(0,$B28-((E$5<Q$5)*F28+(K$5<Q$5)*L28+(W$5<Q$5)*X28+(AC$5<Q$5)*AD28+(AI$5<Q$5)*AJ28+(AO$5<Q$5)*AP28+(AU$5<Q$5)*AV28))) | T28: =IF(R28-S28<0.005,0,R28-S28) | U28: =Z27 | V28: =U28*Plan!D9/100/12 | W28: =MIN(Plan!E9,U28+V28) | X28: =U28+V28-W28 | Y28: =MIN(X28,MAX(0,$B28-((E$5<W$5)*F28+(K$5<W$5)*L28+(Q$5<W$5)*R28+(AC$5<W$5)*AD28+(AI$5<W$5)*AJ28+(AO$5<W$5)*AP28+(AU$5<W$5)*AV28))) | Z28: =IF(X28-Y28<0.005,0,X28-Y28) | AA28: =AF27 | AB28: =AA28*Plan!D10/100/12 | AC28: =MIN(Plan!E10,AA28+AB28) | AD28: =AA28+AB28-AC28 | AE28: =MIN(AD28,MAX(0,$B28-((E$5<AC$5)*F28+(K$5<AC$5)*L28+(Q$5<AC$5)*R28+(W$5<AC$5)*X28+(AI$5<AC$5)*AJ28+(AO$5<AC$5)*AP28+(AU$5<AC$5)*AV28))) | AF28: =IF(AD28-AE28<0.005,0,AD28-AE28) | AG28: =AL27 | AH28: =AG28*Plan!D11/100/12 | AI28: =MIN(Plan!E11,AG28+AH28) | AJ28: =AG28+AH28-AI28 | AK28: =MIN(AJ28,MAX(0,$B28-((E$5<AI$5)*F28+(K$5<AI$5)*L28+(Q$5<AI$5)*R28+(W$5<AI$5)*X28+(AC$5<AI$5)*AD28+(AO$5<AI$5)*AP28+(AU$5<AI$5)*AV28))) | AL28: =IF(AJ28-AK28<0.005,0,AJ28-AK28) | AM28: =AR27 | AN28: =AM28*Plan!D12/100/12 | AO28: =MIN(Plan!E12,AM28+AN28) | AP28: =AM28+AN28-AO28 | AQ28: =MIN(AP28,MAX(0,$B28-((E$5<AO$5)*F28+(K$5<AO$5)*L28+(Q$5<AO$5)*R28+(W$5<AO$5)*X28+(AC$5<AO$5)*AD28+(AI$5<AO$5)*AJ28+(AU$5<AO$5)*AV28))) | AR28: =IF(AP28-AQ28<0.005,0,AP28-AQ28) | AS28: =AX27 | AT28: =AS28*Plan!D13/100/12 | AU28: =MIN(Plan!E13,AS28+AT28) | AV28: =AS28+AT28-AU28 | AW28: =MIN(AV28,MAX(0,$B28-((E$5<AU$5)*F28+(K$5<AU$5)*L28+(Q$5<AU$5)*R28+(W$5<AU$5)*X28+(AC$5<AU$5)*AD28+(AI$5<AU$5)*AJ28+(AO$5<AU$5)*AP28))) | AX28: =IF(AV28-AW28<0.005,0,AV28-AW28) | BC28: =H28+N28+T28+Z28+AF28+AL28+AR28+AX28
A29: 23 | B29: =MAX(0,$B$3-(E29+K29+Q29+W29+AC29+AI29+AO29+AU29)) | C29: =H28 | D29: =C29*Plan!D6/100/12 | E29: =MIN(Plan!E6,C29+D29) | F29: =C29+D29-E29 | G29: =MIN(F29,MAX(0,$B29-((K$5<E$5)*L29+(Q$5<E$5)*R29+(W$5<E$5)*X29+(AC$5<E$5)*AD29+(AI$5<E$5)*AJ29+(AO$5<E$5)*AP29+(AU$5<E$5)*AV29))) | H29: =IF(F29-G29<0.005,0,F29-G29) | I29: =N28 | J29: =I29*Plan!D7/100/12 | K29: =MIN(Plan!E7,I29+J29) | L29: =I29+J29-K29 | M29: =MIN(L29,MAX(0,$B29-((E$5<K$5)*F29+(Q$5<K$5)*R29+(W$5<K$5)*X29+(AC$5<K$5)*AD29+(AI$5<K$5)*AJ29+(AO$5<K$5)*AP29+(AU$5<K$5)*AV29))) | N29: =IF(L29-M29<0.005,0,L29-M29) | O29: =T28 | P29: =O29*Plan!D8/100/12 | Q29: =MIN(Plan!E8,O29+P29) | R29: =O29+P29-Q29 | S29: =MIN(R29,MAX(0,$B29-((E$5<Q$5)*F29+(K$5<Q$5)*L29+(W$5<Q$5)*X29+(AC$5<Q$5)*AD29+(AI$5<Q$5)*AJ29+(AO$5<Q$5)*AP29+(AU$5<Q$5)*AV29))) | T29: =IF(R29-S29<0.005,0,R29-S29) | U29: =Z28 | V29: =U29*Plan!D9/100/12 | W29: =MIN(Plan!E9,U29+V29) | X29: =U29+V29-W29 | Y29: =MIN(X29,MAX(0,$B29-((E$5<W$5)*F29+(K$5<W$5)*L29+(Q$5<W$5)*R29+(AC$5<W$5)*AD29+(AI$5<W$5)*AJ29+(AO$5<W$5)*AP29+(AU$5<W$5)*AV29))) | Z29: =IF(X29-Y29<0.005,0,X29-Y29) | AA29: =AF28 | AB29: =AA29*Plan!D10/100/12 | AC29: =MIN(Plan!E10,AA29+AB29) | AD29: =AA29+AB29-AC29 | AE29: =MIN(AD29,MAX(0,$B29-((E$5<AC$5)*F29+(K$5<AC$5)*L29+(Q$5<AC$5)*R29+(W$5<AC$5)*X29+(AI$5<AC$5)*AJ29+(AO$5<AC$5)*AP29+(AU$5<AC$5)*AV29))) | AF29: =IF(AD29-AE29<0.005,0,AD29-AE29) | AG29: =AL28 | AH29: =AG29*Plan!D11/100/12 | AI29: =MIN(Plan!E11,AG29+AH29) | AJ29: =AG29+AH29-AI29 | AK29: =MIN(AJ29,MAX(0,$B29-((E$5<AI$5)*F29+(K$5<AI$5)*L29+(Q$5<AI$5)*R29+(W$5<AI$5)*X29+(AC$5<AI$5)*AD29+(AO$5<AI$5)*AP29+(AU$5<AI$5)*AV29))) | AL29: =IF(AJ29-AK29<0.005,0,AJ29-AK29) | AM29: =AR28 | AN29: =AM29*Plan!D12/100/12 | AO29: =MIN(Plan!E12,AM29+AN29) | AP29: =AM29+AN29-AO29 | AQ29: =MIN(AP29,MAX(0,$B29-((E$5<AO$5)*F29+(K$5<AO$5)*L29+(Q$5<AO$5)*R29+(W$5<AO$5)*X29+(AC$5<AO$5)*AD29+(AI$5<AO$5)*AJ29+(AU$5<AO$5)*AV29))) | AR29: =IF(AP29-AQ29<0.005,0,AP29-AQ29) | AS29: =AX28 | AT29: =AS29*Plan!D13/100/12 | AU29: =MIN(Plan!E13,AS29+AT29) | AV29: =AS29+AT29-AU29 | AW29: =MIN(AV29,MAX(0,$B29-((E$5<AU$5)*F29+(K$5<AU$5)*L29+(Q$5<AU$5)*R29+(W$5<AU$5)*X29+(AC$5<AU$5)*AD29+(AI$5<AU$5)*AJ29+(AO$5<AU$5)*AP29))) | AX29: =IF(AV29-AW29<0.005,0,AV29-AW29) | BC29: =H29+N29+T29+Z29+AF29+AL29+AR29+AX29
